Workbook

Sheet League Draft Order
A2: Owner | B2: Team Pick From | C2: Pick | D2: Needs | E2: CBS ADP | F2: Projected Pick
A3: Barry Sanders | B3: Barry Sanders | C3: 1.1 | D3: RB/QB | F3: Jeremiyah Love
A4: Natural Born Spillers | B4: Natural Born Spillers | C4: 1.2 | D4: WR | F4: Carnell Tate
A5: Flexorcist | B5: Run Jalen Run | C5: 1.3 | D5: RB/WR | F5: Makai Lemon
A6: Hitmen | B6: Hitmen | C6: 1.4 | D6: WR | F6: Jordan Tyson
A7: Furies | B7: Hot Tub | C7: 1.5 | F7: Jordyn Tyson/Kenyon Sadiq
A8: Furies | B8: House Pain | C8: 1.6 | F8: Kenyon Sadiq/Jadarian Price/Jonah Coleman
A9: Flexorcist | B9: Flexorcist | C9: 1.7 | D9: RB/WR | F9: Jadarian Price
A10: V-Rilla | B10: V-Rilla | C10: 1.8 | D10: WR/BPA | F10: Omar Cooper
A11: Flexorcist | B11: Hurts So Good | C11: 1.9 | D11: RB/WR | F11: Denzel Boston
A12: Hurts So Good | B12: Prestige | C12: 1.1 | D12: TE/Flex | F12: Eli Stowers
A13: Flexorcist | B13: Flint Tropic | C13: 1.11 | D13: RB/WR | F13: Mike Washington
A14: Furies | B14: Furies | C14: 1.12 | F14: Eli Stowers/Jonah Coleman/Nick Singleton?/Denzel Boston/K.C. Concepcion/Antonio Williams/
A15: Barry Sanders | B15: Barry Sanders | C15: 2.1 | D15: RB/QB | F15: K.C. Concepcion
A16: Barry Sanders | B16: Natural Born Spillers | C16: 2.2 | D16: RB/QB | F16: Fernando Mendoza
A17: Barry Sanders | B17: Run Jalen Run | C17: 2.3 | D17: RB/QB | F17: Jonah Coleman
A18: Hitmen | B18: Hitmen | C18: 2.4 | D18: Flex | F18: Emmett Johnson
A19: Hot Tub | B19: Hot Tub | C19: 2.5 | D19: RB/BPA | F19: Nick Singleton
A20: Hurts So Good | B20: House Pain | C20: 2.6 | D20: TE/Flex | F20: Ty Simpson
A21: Flexorcist | B21: Flexorcist | C21: 2.7 | D21: RB/WR | F21: Chris Bell
A22: Hot Tub | B22: V-Rilla | C22: 2.8 | D22: RB/BPA | F22: Chris Brazzell II
A23: Barry Sanders | B23: Hurts So Good | C23: 2.9 | D23: RB/QB | F23: Germie Bernard*
A24: Barry Sanders | B24: Prestige | C24: 2.1 | D24: RB/QB | F24: Elijah Sarratt
A25: Hurts So Good | B25: Flint Tropic | C25: 2.11 | D25: TE/Flex | F25: Zachariah Branch
A26: Furies | B26: Furies | C26: 2.12 | F26: Leveon Moss***/Kaytron Allen***/Demond Clairborne/Kaelen Black (SF)/Eli Heidenreich***/Chris Bell**/Caleb Douglas (Sleeper!!)
A27: Barry Sanders | B27: Barry Sanders | C27: 3.1 | D27: RB/QB | F27: Malachi Fields
A28: Natural Born Spillers | B28: Natural Born Spillers | C28: 3.2 | D28: BPA | F28: Kaytron Allen
A29: V-Rilla | B29: Run Jalen Run | C29: 3.3 | D29: WR/BPA | F29: Skyler Bell
A30: Hitmen | B30: Hitmen | C30: 3.4 | D30: Flex | F30: Demond Claiborne
A31: V-Rilla | B31: Hot Tub | C31: 3.5 | D31: WR/BPA | F31: Bryce Lance
A32: Hurts So Good | B32: House Pain | C32: 3.6 | D32: TE/Flex | F32: Ted Hurst
A33: Flexorcist | B33: Flexorcist | C33: 3.7 | D33: RB/WR | F33: Deion Burks
A34: V-Rilla | B34: V-Rilla | C34: 3.8 | D34: WR/BPA | F34: Max Klare
A35: Furies | B35: Hurts So Good | C35: 3.9 | F35: Eli Raridon (NE)***/Caleb Douglas (Sleeper***)/Bryce Lance (N.O.)***/Cyrus Allen?
A36: Hitmen | B36: Prestige | C36: 3.1 | D36: Flex | F36: Seth McGowan
A37: Furies | B37: Flint Tropic | C37: 3.11 | F37: Draft A Bum
A38: Furies | B38: Furies | C38: 3.12 | F38: Draft A Bum

Sheet QB Model Page
B1: Quarterbacks | C1: Ht. Inches | D1: Weight | E1: 40 Yard Dash | F1: Ht. Adj. Speed | G1: Rush Yds Per Game | H1: Rush TDs Game | I1: ANY/A | J1: Yards/ DB | K1: EPA/ DB | L1: Passing TD% | M1: Passing Int% | N1: BTT Rate% | O1: TWP Rate% | P1: Adj. Accuracy% | Q1: PFF Pass Grade | R1: Avg Time To Throw | S1: Sack% | T1: S.O.S | U1: Upside Score | V1: Safety Score | W1: Draft Age | X1: Draft Position | Y1: Team | Z1: Landing Bonus | AA1: Final Ranking | AB1: Tier | AC1: Team | AD1: Landing Bonus
B2: Fernando Mendoza (Indiana) | C2: 77 | D2: 225 | E2: 4.78 | F2: =ROUND((D2*200)/(E2^4)*(C2/75),2) -> 88.5 | G2: 26.33 | H2: 0.33 | I2: 8.53 | J2: 7.26 | K2: 0.459 | L2: 7.38 | M2: 1.55 | N2: 4.27 | O2: 3.059 | P2: 77.216 | Q2: 83.042 | R2: 2.629 | S2: 7.232 | T2: 1 | U2: =ROUND(MIN(20,MAX(0,K2/0.45*20))+MIN(15,MAX(0,(I2-5)/7*15))+MIN(15,MAX(0,N2/6*15))+MIN(15,MAX(0,G2/80*15))+MIN(15,MAX(0,F2/120*15))+MIN(10,MAX(0,(J2-6)/5*10))+MIN(10,MAX(0,Q2/90*10)),1) -> 66 | V2: =ROUND(MIN(25,MAX(0,L2/10*25))+MIN(25,MAX(0,(1-M2/5)*25))+MIN(20,MAX(0,P2/78*20))+MIN(15,MAX(0,(J2-6)/5*15))+MIN(10,MAX(0,(MAX(0,2.5-O2)/2.5)*10))+IF(ISNUMBER(X2),MAX(0,5-((INT(X2)-1)*32+ROUND(MOD(X2,1)*100,0))*0.02),IF(LOWER(X2)="UDFA",0.5,3)),1) -> 64.3 | W2: 22 | X2: 1.01 | Y2: LV | Z2: =MAX(0,IFERROR(VLOOKUP(Y2,$AC$2:$AD$34,2,FALSE()),0)) -> 0.5 | AA2: =IF(AND(LOWER(X2)="udfa",OR(Y2="N/A",Y2="")),-999,INT(MIN(96.9,(IF((IF(ISNUMBER(X2),12*EXP(-0.0179*((INT(X2)-1)*32+ROUND(MOD(X2,1)*100,0)-1)),IF(LOWER(X2)="UDFA",0.3,0))+IF(C2>=76,8,IF(C2>=74,6,IF(C2>=73,3,IF(C2>=72,0,IF(C2>=71,-4,-8)))))+(MIN(25.5,MAX(0,K2/0.45*25.5))+MIN(17,MAX(0,I2/9.5*17))+MIN(12,MAX(0,N2/6*12))+MIN(11.5,MIN(10,MAX(0,G2/70*10))+MIN(3.75,MAX(0,H2/0.8*3.75)))+MIN(10.25,MAX(0,J2/8*10.25))+MIN(7.5,MAX(0,L2/7*7.5))+MIN(7.5,MAX(0,Q2/90*7.5))+MIN(6.25,MAX(0,P2/78*6.25))-MIN(8,MAX(0,(MAX(0,O2-2)/2)*8))-MIN(8,MAX(0,IF(M2<=1.5,0,IF(M2<=2.5,(M2-1.5)*4,4+(M2-2.5)*8))))-MIN(5,MAX(0,(MAX(0,S2-5)/3)*5))-MIN(3,MAX(0,(MAX(0,R2-2.9)/0.5)*3)))*T2-MAX(0,(W2-22)*3.5))>60,60+SQRT((IF(ISNUMBER(X2),12*EXP(-0.0179*((INT(X2)-1)*32+ROUND(MOD(X2,1)*100,0)-1)),IF(LOWER(X2)="UDFA",0.3,0))+IF(C2>=76,8,IF(C2>=74,6,IF(C2>=73,3,IF(C2>=72,0,IF(C2>=71,-4,-8)))))+(MIN(25.5,MAX(0,K2/0.45*25.5))+MIN(17,MAX(0,I2/9.5*17))+MIN(12,MAX(0,N2/6*12))+MIN(11.5,MIN(10,MAX(0,G2/70*10))+MIN(3.75,MAX(0,H2/0.8*3.75)))+MIN(10.25,MAX(0,J2/8*10.25))+MIN(7.5,MAX(0,L2/7*7.5))+MIN(7.5,MAX(0,Q2/90*7.5))+MIN(6.25,MAX(0,P2/78*6.25))-MIN(8,MAX(0,(MAX(0,O2-2)/2)*8))-MIN(8,MAX(0,IF(M2<=1.5,0,IF(M2<=2.5,(M2-1.5)*4,4+(M2-2.5)*8))))-MIN(5,MAX(0,(MAX(0,S2-5)/3)*5))-MIN(3,MAX(0,(MAX(0,R2-2.9)/0.5)*3)))*T2-MAX(0,(W2-22)*3.5))-60)*5,(IF(ISNUMBER(X2),12*EXP(-0.0179*((INT(X2)-1)*32+ROUND(MOD(X2,1)*100,0)-1)),IF(LOWER(X2)="UDFA",0.3,0))+IF(C2>=76,8,IF(C2>=74,6,IF(C2>=73,3,IF(C2>=72,0,IF(C2>=71,-4,-8)))))+(MIN(25.5,MAX(0,K2/0.45*25.5))+MIN(17,MAX(0,I2/9.5*17))+MIN(12,MAX(0,N2/6*12))+MIN(11.5,MIN(10,MAX(0,G2/70*10))+MIN(3.75,MAX(0,H2/0.8*3.75)))+MIN(10.25,MAX(0,J2/8*10.25))+MIN(7.5,MAX(0,L2/7*7.5))+MIN(7.5,MAX(0,Q2/90*7.5))+MIN(6.25,MAX(0,P2/78*6.25))-MIN(8,MAX(0,(MAX(0,O2-2)/2)*8))-MIN(8,MAX(0,IF(M2<=1.5,0,IF(M2<=2.5,(M2-1.5)*4,4+(M2-2.5)*8))))-MIN(5,MAX(0,(MAX(0,S2-5)/3)*5))-MIN(3,MAX(0,(MAX(0,R2-2.9)/0.5)*3)))*T2-MAX(0,(W2-22)*3.5))))*0.98)+Z2)) -> 88 | AB2: =IF(AA2=-999,"",IF(AA2>=92,"Franchise QB",IF(AA2>=88,"High-end Starter",IF(AA2>=84,"Developmental Starter",IF(AA2>=71,"Backup / Camp QB",IF(AA2>=58,"Deep Stash","Cut")))))) -> High-end Starter | AC2: ARI | AD2: 1.46
B3: Ty Simpson (Alabama) | C3: 73 | D3: 211 | E3: 4.68 | F3: =ROUND((D3*200)/(E3^4)*(C3/75),2) -> 85.62 | G3: 16.33 | H3: 0.14 | I3: 7.67 | J3: 6.56 | K3: 0.33 | L3: 5.61 | M3: 1 | N3: 5.891 | O3: 2.857 | P3: 75.125 | Q3: 80.73 | R3: 2.938 | S3: 5.414 | T3: 1 | U3: =ROUND(MIN(20,MAX(0,K3/0.45*20))+MIN(15,MAX(0,(I3-5)/7*15))+MIN(15,MAX(0,N3/6*15))+MIN(15,MAX(0,G3/80*15))+MIN(15,MAX(0,F3/120*15))+MIN(10,MAX(0,(J3-6)/5*10))+MIN(10,MAX(0,Q3/90*10)),1) -> 59 | V3: =ROUND(MIN(25,MAX(0,L3/10*25))+MIN(25,MAX(0,(1-M3/5)*25))+MIN(20,MAX(0,P3/78*20))+MIN(15,MAX(0,(J3-6)/5*15))+MIN(10,MAX(0,(MAX(0,2.5-O3)/2.5)*10))+IF(ISNUMBER(X3),MAX(0,5-((INT(X3)-1)*32+ROUND(MOD(X3,1)*100,0))*0.02),IF(LOWER(X3)="UDFA",0.5,3)),1) -> 59.7 | W3: 22 | X3: 1.13 | Y3: LAR | Z3: =MAX(0,IFERROR(VLOOKUP(Y3,$AC$2:$AD$34,2,FALSE()),0)) -> 2.55 | AA3: =IF(AND(LOWER(X3)="udfa",OR(Y3="N/A",Y3="")),-999,INT(MIN(96.9,(IF((IF(ISNUMBER(X3),12*EXP(-0.0179*((INT(X3)-1)*32+ROUND(MOD(X3,1)*100,0)-1)),IF(LOWER(X3)="UDFA",0.3,0))+IF(C3>=76,8,IF(C3>=74,6,IF(C3>=73,3,IF(C3>=72,0,IF(C3>=71,-4,-8)))))+(MIN(25.5,MAX(0,K3/0.45*25.5))+MIN(17,MAX(0,I3/9.5*17))+MIN(12,MAX(0,N3/6*12))+MIN(11.5,MIN(10,MAX(0,G3/70*10))+MIN(3.75,MAX(0,H3/0.8*3.75)))+MIN(10.25,MAX(0,J3/8*10.25))+MIN(7.5,MAX(0,L3/7*7.5))+MIN(7.5,MAX(0,Q3/90*7.5))+MIN(6.25,MAX(0,P3/78*6.25))-MIN(8,MAX(0,(MAX(0,O3-2)/2)*8))-MIN(8,MAX(0,IF(M3<=1.5,0,IF(M3<=2.5,(M3-1.5)*4,4+(M3-2.5)*8))))-MIN(5,MAX(0,(MAX(0,S3-5)/3)*5))-MIN(3,MAX(0,(MAX(0,R3-2.9)/0.5)*3)))*T3-MAX(0,(W3-22)*3.5))>60,60+SQRT((IF(ISNUMBER(X3),12*EXP(-0.0179*((INT(X3)-1)*32+ROUND(MOD(X3,1)*100,0)-1)),IF(LOWER(X3)="UDFA",0.3,0))+IF(C3>=76,8,IF(C3>=74,6,IF(C3>=73,3,IF(C3>=72,0,IF(C3>=71,-4,-8)))))+(MIN(25.5,MAX(0,K3/0.45*25.5))+MIN(17,MAX(0,I3/9.5*17))+MIN(12,MAX(0,N3/6*12))+MIN(11.5,MIN(10,MAX(0,G3/70*10))+MIN(3.75,MAX(0,H3/0.8*3.75)))+MIN(10.25,MAX(0,J3/8*10.25))+MIN(7.5,MAX(0,L3/7*7.5))+MIN(7.5,MAX(0,Q3/90*7.5))+MIN(6.25,MAX(0,P3/78*6.25))-MIN(8,MAX(0,(MAX(0,O3-2)/2)*8))-MIN(8,MAX(0,IF(M3<=1.5,0,IF(M3<=2.5,(M3-1.5)*4,4+(M3-2.5)*8))))-MIN(5,MAX(0,(MAX(0,S3-5)/3)*5))-MIN(3,MAX(0,(MAX(0,R3-2.9)/0.5)*3)))*T3-MAX(0,(W3-22)*3.5))-60)*5,(IF(ISNUMBER(X3),12*EXP(-0.0179*((INT(X3)-1)*32+ROUND(MOD(X3,1)*100,0)-1)),IF(LOWER(X3)="UDFA",0.3,0))+IF(C3>=76,8,IF(C3>=74,6,IF(C3>=73,3,IF(C3>=72,0,IF(C3>=71,-4,-8)))))+(MIN(25.5,MAX(0,K3/0.45*25.5))+MIN(17,MAX(0,I3/9.5*17))+MIN(12,MAX(0,N3/6*12))+MIN(11.5,MIN(10,MAX(0,G3/70*10))+MIN(3.75,MAX(0,H3/0.8*3.75)))+MIN(10.25,MAX(0,J3/8*10.25))+MIN(7.5,MAX(0,L3/7*7.5))+MIN(7.5,MAX(0,Q3/90*7.5))+MIN(6.25,MAX(0,P3/78*6.25))-MIN(8,MAX(0,(MAX(0,O3-2)/2)*8))-MIN(8,MAX(0,IF(M3<=1.5,0,IF(M3<=2.5,(M3-1.5)*4,4+(M3-2.5)*8))))-MIN(5,MAX(0,(MAX(0,S3-5)/3)*5))-MIN(3,MAX(0,(MAX(0,R3-2.9)/0.5)*3)))*T3-MAX(0,(W3-22)*3.5))))*0.98)+Z3)) -> 84 | AB3: =IF(AA3=-999,"",IF(AA3>=92,"Franchise QB",IF(AA3>=88,"High-end Starter",IF(AA3>=84,"Developmental Starter",IF(AA3>=71,"Backup / Camp QB",IF(AA3>=58,"Deep Stash","Cut")))))) -> Developmental Starter | AC3: ATL | AD3: 1.02
B4: Haynes King (Georgia Tech) | C4: 74 | D4: 212 | E4: 4.46 | F4: =ROUND((D4*200)/(E4^4)*(C4/75),2) -> 105.73 | G4: 69.57 | H4: 1.13 | I4: 8.01 | J4: 7.43 | K4: 0.354 | L4: 4.4 | M4: 1.26 | N4: 3.496 | O4: 1 | P4: 80.4 | Q4: 80.942 | R4: 2.57 | S4: 2.626 | T4: 1 | U4: =ROUND(MIN(20,MAX(0,K4/0.45*20))+MIN(15,MAX(0,(I4-5)/7*15))+MIN(15,MAX(0,N4/6*15))+MIN(15,MAX(0,G4/80*15))+MIN(15,MAX(0,F4/120*15))+MIN(10,MAX(0,(J4-6)/5*10))+MIN(10,MAX(0,Q4/90*10)),1) -> 69 | V4: =ROUND(MIN(25,MAX(0,L4/10*25))+MIN(25,MAX(0,(1-M4/5)*25))+MIN(20,MAX(0,P4/78*20))+MIN(15,MAX(0,(J4-6)/5*15))+MIN(10,MAX(0,(MAX(0,2.5-O4)/2.5)*10))+IF(ISNUMBER(X4),MAX(0,5-((INT(X4)-1)*32+ROUND(MOD(X4,1)*100,0))*0.02),IF(LOWER(X4)="UDFA",0.5,3)),1) -> 60.5 | W4: 25 | X4: UDFA | Y4: CAR | Z4: =MAX(0,IFERROR(VLOOKUP(Y4,$AC$2:$AD$34,2,FALSE()),0)) -> 1.14 | AA4: =IF(AND(LOWER(X4)="udfa",OR(Y4="N/A",Y4="")),-999,INT(MIN(96.9,(IF((IF(ISNUMBER(X4),12*EXP(-0.0179*((INT(X4)-1)*32+ROUND(MOD(X4,1)*100,0)-1)),IF(LOWER(X4)="UDFA",0.3,0))+IF(C4>=76,8,IF(C4>=74,6,IF(C4>=73,3,IF(C4>=72,0,IF(C4>=71,-4,-8)))))+(MIN(25.5,MAX(0,K4/0.45*25.5))+MIN(17,MAX(0,I4/9.5*17))+MIN(12,MAX(0,N4/6*12))+MIN(11.5,MIN(10,MAX(0,G4/70*10))+MIN(3.75,MAX(0,H4/0.8*3.75)))+MIN(10.25,MAX(0,J4/8*10.25))+MIN(7.5,MAX(0,L4/7*7.5))+MIN(7.5,MAX(0,Q4/90*7.5))+MIN(6.25,MAX(0,P4/78*6.25))-MIN(8,MAX(0,(MAX(0,O4-2)/2)*8))-MIN(8,MAX(0,IF(M4<=1.5,0,IF(M4<=2.5,(M4-1.5)*4,4+(M4-2.5)*8))))-MIN(5,MAX(0,(MAX(0,S4-5)/3)*5))-MIN(3,MAX(0,(MAX(0,R4-2.9)/0.5)*3)))*T4-MAX(0,(W4-22)*3.5))>60,60+SQRT((IF(ISNUMBER(X4),12*EXP(-0.0179*((INT(X4)-1)*32+ROUND(MOD(X4,1)*100,0)-1)),IF(LOWER(X4)="UDFA",0.3,0))+IF(C4>=76,8,IF(C4>=74,6,IF(C4>=73,3,IF(C4>=72,0,IF(C4>=71,-4,-8)))))+(MIN(25.5,MAX(0,K4/0.45*25.5))+MIN(17,MAX(0,I4/9.5*17))+MIN(12,MAX(0,N4/6*12))+MIN(11.5,MIN(10,MAX(0,G4/70*10))+MIN(3.75,MAX(0,H4/0.8*3.75)))+MIN(10.25,MAX(0,J4/8*10.25))+MIN(7.5,MAX(0,L4/7*7.5))+MIN(7.5,MAX(0,Q4/90*7.5))+MIN(6.25,MAX(0,P4/78*6.25))-MIN(8,MAX(0,(MAX(0,O4-2)/2)*8))-MIN(8,MAX(0,IF(M4<=1.5,0,IF(M4<=2.5,(M4-1.5)*4,4+(M4-2.5)*8))))-MIN(5,MAX(0,(MAX(0,S4-5)/3)*5))-MIN(3,MAX(0,(MAX(0,R4-2.9)/0.5)*3)))*T4-MAX(0,(W4-22)*3.5))-60)*5,(IF(ISNUMBER(X4),12*EXP(-0.0179*((INT(X4)-1)*32+ROUND(MOD(X4,1)*100,0)-1)),IF(LOWER(X4)="UDFA",0.3,0))+IF(C4>=76,8,IF(C4>=74,6,IF(C4>=73,3,IF(C4>=72,0,IF(C4>=71,-4,-8)))))+(MIN(25.5,MAX(0,K4/0.45*25.5))+MIN(17,MAX(0,I4/9.5*17))+MIN(12,MAX(0,N4/6*12))+MIN(11.5,MIN(10,MAX(0,G4/70*10))+MIN(3.75,MAX(0,H4/0.8*3.75)))+MIN(10.25,MAX(0,J4/8*10.25))+MIN(7.5,MAX(0,L4/7*7.5))+MIN(7.5,MAX(0,Q4/90*7.5))+MIN(6.25,MAX(0,P4/78*6.25))-MIN(8,MAX(0,(MAX(0,O4-2)/2)*8))-MIN(8,MAX(0,IF(M4<=1.5,0,IF(M4<=2.5,(M4-1.5)*4,4+(M4-2.5)*8))))-MIN(5,MAX(0,(MAX(0,S4-5)/3)*5))-MIN(3,MAX(0,(MAX(0,R4-2.9)/0.5)*3)))*T4-MAX(0,(W4-22)*3.5))))*0.98)+Z4)) -> 79 | AB4: =IF(AA4=-999,"",IF(AA4>=92,"Franchise QB",IF(AA4>=88,"High-end Starter",IF(AA4>=84,"Developmental Starter",IF(AA4>=71,"Backup / Camp QB",IF(AA4>=58,"Deep Stash","Cut")))))) -> Backup / Camp QB | AC4: BAL | AD4: 0.97
B5: Diego Pavia (Vanderbilt) | C5: 70 | D5: 207 | E5: 4.64 | F5: =ROUND((D5*200)/(E5^4)*(C5/75),2) -> 83.36 | G5: 72.35 | H5: 0.69 | I5: 8.76 | J5: 7.22 | K5: 0.517 | L5: 7.23 | M5: 1.77 | N5: 6.745 | O5: 1.976 | P5: 75.758 | Q5: 88.211 | R5: 2.918 | S5: 4.469 | T5: 1 | U5: =ROUND(MIN(20,MAX(0,K5/0.45*20))+MIN(15,MAX(0,(I5-5)/7*15))+MIN(15,MAX(0,N5/6*15))+MIN(15,MAX(0,G5/80*15))+MIN(15,MAX(0,F5/120*15))+MIN(10,MAX(0,(J5-6)/5*10))+MIN(10,MAX(0,Q5/90*10)),1) -> 79.3 | V5: =ROUND(MIN(25,MAX(0,L5/10*25))+MIN(25,MAX(0,(1-M5/5)*25))+MIN(20,MAX(0,P5/78*20))+MIN(15,MAX(0,(J5-6)/5*15))+MIN(10,MAX(0,(MAX(0,2.5-O5)/2.5)*10))+IF(ISNUMBER(X5),MAX(0,5-((INT(X5)-1)*32+ROUND(MOD(X5,1)*100,0))*0.02),IF(LOWER(X5)="UDFA",0.5,3)),1) -> 59.9 | W5: 25 | X5: UDFA | Y5: BAL | Z5: =MAX(0,IFERROR(VLOOKUP(Y5,$AC$2:$AD$34,2,FALSE()),0)) -> 0.97 | AA5: =IF(AND(LOWER(X5)="udfa",OR(Y5="N/A",Y5="")),-999,INT(MIN(96.9,(IF((IF(ISNUMBER(X5),12*EXP(-0.0179*((INT(X5)-1)*32+ROUND(MOD(X5,1)*100,0)-1)),IF(LOWER(X5)="UDFA",0.3,0))+IF(C5>=76,8,IF(C5>=74,6,IF(C5>=73,3,IF(C5>=72,0,IF(C5>=71,-4,-8)))))+(MIN(25.5,MAX(0,K5/0.45*25.5))+MIN(17,MAX(0,I5/9.5*17))+MIN(12,MAX(0,N5/6*12))+MIN(11.5,MIN(10,MAX(0,G5/70*10))+MIN(3.75,MAX(0,H5/0.8*3.75)))+MIN(10.25,MAX(0,J5/8*10.25))+MIN(7.5,MAX(0,L5/7*7.5))+MIN(7.5,MAX(0,Q5/90*7.5))+MIN(6.25,MAX(0,P5/78*6.25))-MIN(8,MAX(0,(MAX(0,O5-2)/2)*8))-MIN(8,MAX(0,IF(M5<=1.5,0,IF(M5<=2.5,(M5-1.5)*4,4+(M5-2.5)*8))))-MIN(5,MAX(0,(MAX(0,S5-5)/3)*5))-MIN(3,MAX(0,(MAX(0,R5-2.9)/0.5)*3)))*T5-MAX(0,(W5-22)*3.5))>60,60+SQRT((IF(ISNUMBER(X5),12*EXP(-0.0179*((INT(X5)-1)*32+ROUND(MOD(X5,1)*100,0)-1)),IF(LOWER(X5)="UDFA",0.3,0))+IF(C5>=76,8,IF(C5>=74,6,IF(C5>=73,3,IF(C5>=72,0,IF(C5>=71,-4,-8)))))+(MIN(25.5,MAX(0,K5/0.45*25.5))+MIN(17,MAX(0,I5/9.5*17))+MIN(12,MAX(0,N5/6*12))+MIN(11.5,MIN(10,MAX(0,G5/70*10))+MIN(3.75,MAX(0,H5/0.8*3.75)))+MIN(10.25,MAX(0,J5/8*10.25))+MIN(7.5,MAX(0,L5/7*7.5))+MIN(7.5,MAX(0,Q5/90*7.5))+MIN(6.25,MAX(0,P5/78*6.25))-MIN(8,MAX(0,(MAX(0,O5-2)/2)*8))-MIN(8,MAX(0,IF(M5<=1.5,0,IF(M5<=2.5,(M5-1.5)*4,4+(M5-2.5)*8))))-MIN(5,MAX(0,(MAX(0,S5-5)/3)*5))-MIN(3,MAX(0,(MAX(0,R5-2.9)/0.5)*3)))*T5-MAX(0,(W5-22)*3.5))-60)*5,(IF(ISNUMBER(X5),12*EXP(-0.0179*((INT(X5)-1)*32+ROUND(MOD(X5,1)*100,0)-1)),IF(LOWER(X5)="UDFA",0.3,0))+IF(C5>=76,8,IF(C5>=74,6,IF(C5>=73,3,IF(C5>=72,0,IF(C5>=71,-4,-8)))))+(MIN(25.5,MAX(0,K5/0.45*25.5))+MIN(17,MAX(0,I5/9.5*17))+MIN(12,MAX(0,N5/6*12))+MIN(11.5,MIN(10,MAX(0,G5/70*10))+MIN(3.75,MAX(0,H5/0.8*3.75)))+MIN(10.25,MAX(0,J5/8*10.25))+MIN(7.5,MAX(0,L5/7*7.5))+MIN(7.5,MAX(0,Q5/90*7.5))+MIN(6.25,MAX(0,P5/78*6.25))-MIN(8,MAX(0,(MAX(0,O5-2)/2)*8))-MIN(8,MAX(0,IF(M5<=1.5,0,IF(M5<=2.5,(M5-1.5)*4,4+(M5-2.5)*8))))-MIN(5,MAX(0,(MAX(0,S5-5)/3)*5))-MIN(3,MAX(0,(MAX(0,R5-2.9)/0.5)*3)))*T5-MAX(0,(W5-22)*3.5))))*0.98)+Z5)) -> 79 | AB5: =IF(AA5=-999,"",IF(AA5>=92,"Franchise QB",IF(AA5>=88,"High-end Starter",IF(AA5>=84,"Developmental Starter",IF(AA5>=71,"Backup / Camp QB",IF(AA5>=58,"Deep Stash","Cut")))))) -> Backup / Camp QB | AC5: BUF | AD5: 1.53
B6: Cade Klubnik (Clemson) | C6: 74 | D6: 207 | E6: 4.69 | F6: =ROUND((D6*200)/(E6^4)*(C6/75),2) -> 84.43 | G6: 31.19 | H6: 0.42 | I6: 7.64 | J6: 6.76 | K6: 0.234 | L6: 5.87 | M6: 1.35 | N6: 4.698 | O6: 2.256 | P6: 75.424 | Q6: 83.179 | R6: 2.671 | S6: 4.337 | T6: 1 | U6: =ROUND(MIN(20,MAX(0,K6/0.45*20))+MIN(15,MAX(0,(I6-5)/7*15))+MIN(15,MAX(0,N6/6*15))+MIN(15,MAX(0,G6/80*15))+MIN(15,MAX(0,F6/120*15))+MIN(10,MAX(0,(J6-6)/5*10))+MIN(10,MAX(0,Q6/90*10)),1) -> 55 | V6: =ROUND(MIN(25,MAX(0,L6/10*25))+MIN(25,MAX(0,(1-M6/5)*25))+MIN(20,MAX(0,P6/78*20))+MIN(15,MAX(0,(J6-6)/5*15))+MIN(10,MAX(0,(MAX(0,2.5-O6)/2.5)*10))+IF(ISNUMBER(X6),MAX(0,5-((INT(X6)-1)*32+ROUND(MOD(X6,1)*100,0))*0.02),IF(LOWER(X6)="UDFA",0.5,3)),1) -> 58.3 | W6: 23 | X6: 4.14 | Y6: NYJ | Z6: =MAX(0,IFERROR(VLOOKUP(Y6,$AC$2:$AD$34,2,FALSE()),0)) -> 0.43 | AA6: =IF(AND(LOWER(X6)="udfa",OR(Y6="N/A",Y6="")),-999,INT(MIN(96.9,(IF((IF(ISNUMBER(X6),12*EXP(-0.0179*((INT(X6)-1)*32+ROUND(MOD(X6,1)*100,0)-1)),IF(LOWER(X6)="UDFA",0.3,0))+IF(C6>=76,8,IF(C6>=74,6,IF(C6>=73,3,IF(C6>=72,0,IF(C6>=71,-4,-8)))))+(MIN(25.5,MAX(0,K6/0.45*25.5))+MIN(17,MAX(0,I6/9.5*17))+MIN(12,MAX(0,N6/6*12))+MIN(11.5,MIN(10,MAX(0,G6/70*10))+MIN(3.75,MAX(0,H6/0.8*3.75)))+MIN(10.25,MAX(0,J6/8*10.25))+MIN(7.5,MAX(0,L6/7*7.5))+MIN(7.5,MAX(0,Q6/90*7.5))+MIN(6.25,MAX(0,P6/78*6.25))-MIN(8,MAX(0,(MAX(0,O6-2)/2)*8))-MIN(8,MAX(0,IF(M6<=1.5,0,IF(M6<=2.5,(M6-1.5)*4,4+(M6-2.5)*8))))-MIN(5,MAX(0,(MAX(0,S6-5)/3)*5))-MIN(3,MAX(0,(MAX(0,R6-2.9)/0.5)*3)))*T6-MAX(0,(W6-22)*3.5))>60,60+SQRT((IF(ISNUMBER(X6),12*EXP(-0.0179*((INT(X6)-1)*32+ROUND(MOD(X6,1)*100,0)-1)),IF(LOWER(X6)="UDFA",0.3,0))+IF(C6>=76,8,IF(C6>=74,6,IF(C6>=73,3,IF(C6>=72,0,IF(C6>=71,-4,-8)))))+(MIN(25.5,MAX(0,K6/0.45*25.5))+MIN(17,MAX(0,I6/9.5*17))+MIN(12,MAX(0,N6/6*12))+MIN(11.5,MIN(10,MAX(0,G6/70*10))+MIN(3.75,MAX(0,H6/0.8*3.75)))+MIN(10.25,MAX(0,J6/8*10.25))+MIN(7.5,MAX(0,L6/7*7.5))+MIN(7.5,MAX(0,Q6/90*7.5))+MIN(6.25,MAX(0,P6/78*6.25))-MIN(8,MAX(0,(MAX(0,O6-2)/2)*8))-MIN(8,MAX(0,IF(M6<=1.5,0,IF(M6<=2.5,(M6-1.5)*4,4+(M6-2.5)*8))))-MIN(5,MAX(0,(MAX(0,S6-5)/3)*5))-MIN(3,MAX(0,(MAX(0,R6-2.9)/0.5)*3)))*T6-MAX(0,(W6-22)*3.5))-60)*5,(IF(ISNUMBER(X6),12*EXP(-0.0179*((INT(X6)-1)*32+ROUND(MOD(X6,1)*100,0)-1)),IF(LOWER(X6)="UDFA",0.3,0))+IF(C6>=76,8,IF(C6>=74,6,IF(C6>=73,3,IF(C6>=72,0,IF(C6>=71,-4,-8)))))+(MIN(25.5,MAX(0,K6/0.45*25.5))+MIN(17,MAX(0,I6/9.5*17))+MIN(12,MAX(0,N6/6*12))+MIN(11.5,MIN(10,MAX(0,G6/70*10))+MIN(3.75,MAX(0,H6/0.8*3.75)))+MIN(10.25,MAX(0,J6/8*10.25))+MIN(7.5,MAX(0,L6/7*7.5))+MIN(7.5,MAX(0,Q6/90*7.5))+MIN(6.25,MAX(0,P6/78*6.25))-MIN(8,MAX(0,(MAX(0,O6-2)/2)*8))-MIN(8,MAX(0,IF(M6<=1.5,0,IF(M6<=2.5,(M6-1.5)*4,4+(M6-2.5)*8))))-MIN(5,MAX(0,(MAX(0,S6-5)/3)*5))-MIN(3,MAX(0,(MAX(0,R6-2.9)/0.5)*3)))*T6-MAX(0,(W6-22)*3.5))))*0.98)+Z6)) -> 77 | AB6: =IF(AA6=-999,"",IF(AA6>=92,"Franchise QB",IF(AA6>=88,"High-end Starter",IF(AA6>=84,"Developmental Starter",IF(AA6>=71,"Backup / Camp QB",IF(AA6>=58,"Deep Stash","Cut")))))) -> Backup / Camp QB | AC6: CAR | AD6: 1.14
B7: Joey Aguilar (Tennessee) | C7: 75 | D7: 229 | E7: 4.85 | F7: =ROUND((D7*200)/(E7^4)*(C7/75),2) -> 82.77 | G7: 7.21 | H7: 0.31 | I7: 8.21 | J7: 8.14 | K7: 0.38 | L7: 5.9 | M7: 2.5 | N7: 5 | O7: 1.9 | P7: 73.5 | Q7: 90.7 | R7: 2.7 | S7: 4.7 | T7: 1 | U7: =ROUND(MIN(20,MAX(0,K7/0.45*20))+MIN(15,MAX(0,(I7-5)/7*15))+MIN(15,MAX(0,N7/6*15))+MIN(15,MAX(0,G7/80*15))+MIN(15,MAX(0,F7/120*15))+MIN(10,MAX(0,(J7-6)/5*10))+MIN(10,MAX(0,Q7/90*10)),1) -> 62.2 | V7: =ROUND(MIN(25,MAX(0,L7/10*25))+MIN(25,MAX(0,(1-M7/5)*25))+MIN(20,MAX(0,P7/78*20))+MIN(15,MAX(0,(J7-6)/5*15))+MIN(10,MAX(0,(MAX(0,2.5-O7)/2.5)*10))+IF(ISNUMBER(X7),MAX(0,5-((INT(X7)-1)*32+ROUND(MOD(X7,1)*100,0))*0.02),IF(LOWER(X7)="UDFA",0.5,3)),1) -> 55.4 | W7: 24 | X7: UDFA | Y7: JAX | Z7: =MAX(0,IFERROR(VLOOKUP(Y7,$AC$2:$AD$34,2,FALSE()),0)) -> 0.43 | AA7: =IF(AND(LOWER(X7)="udfa",OR(Y7="N/A",Y7="")),-999,INT(MIN(96.9,(IF((IF(ISNUMBER(X7),12*EXP(-0.0179*((INT(X7)-1)*32+ROUND(MOD(X7,1)*100,0)-1)),IF(LOWER(X7)="UDFA",0.3,0))+IF(C7>=76,8,IF(C7>=74,6,IF(C7>=73,3,IF(C7>=72,0,IF(C7>=71,-4,-8)))))+(MIN(25.5,MAX(0,K7/0.45*25.5))+MIN(17,MAX(0,I7/9.5*17))+MIN(12,MAX(0,N7/6*12))+MIN(11.5,MIN(10,MAX(0,G7/70*10))+MIN(3.75,MAX(0,H7/0.8*3.75)))+MIN(10.25,MAX(0,J7/8*10.25))+MIN(7.5,MAX(0,L7/7*7.5))+MIN(7.5,MAX(0,Q7/90*7.5))+MIN(6.25,MAX(0,P7/78*6.25))-MIN(8,MAX(0,(MAX(0,O7-2)/2)*8))-MIN(8,MAX(0,IF(M7<=1.5,0,IF(M7<=2.5,(M7-1.5)*4,4+(M7-2.5)*8))))-MIN(5,MAX(0,(MAX(0,S7-5)/3)*5))-MIN(3,MAX(0,(MAX(0,R7-2.9)/0.5)*3)))*T7-MAX(0,(W7-22)*3.5))>60,60+SQRT((IF(ISNUMBER(X7),12*EXP(-0.0179*((INT(X7)-1)*32+ROUND(MOD(X7,1)*100,0)-1)),IF(LOWER(X7)="UDFA",0.3,0))+IF(C7>=76,8,IF(C7>=74,6,IF(C7>=73,3,IF(C7>=72,0,IF(C7>=71,-4,-8)))))+(MIN(25.5,MAX(0,K7/0.45*25.5))+MIN(17,MAX(0,I7/9.5*17))+MIN(12,MAX(0,N7/6*12))+MIN(11.5,MIN(10,MAX(0,G7/70*10))+MIN(3.75,MAX(0,H7/0.8*3.75)))+MIN(10.25,MAX(0,J7/8*10.25))+MIN(7.5,MAX(0,L7/7*7.5))+MIN(7.5,MAX(0,Q7/90*7.5))+MIN(6.25,MAX(0,P7/78*6.25))-MIN(8,MAX(0,(MAX(0,O7-2)/2)*8))-MIN(8,MAX(0,IF(M7<=1.5,0,IF(M7<=2.5,(M7-1.5)*4,4+(M7-2.5)*8))))-MIN(5,MAX(0,(MAX(0,S7-5)/3)*5))-MIN(3,MAX(0,(MAX(0,R7-2.9)/0.5)*3)))*T7-MAX(0,(W7-22)*3.5))-60)*5,(IF(ISNUMBER(X7),12*EXP(-0.0179*((INT(X7)-1)*32+ROUND(MOD(X7,1)*100,0)-1)),IF(LOWER(X7)="UDFA",0.3,0))+IF(C7>=76,8,IF(C7>=74,6,IF(C7>=73,3,IF(C7>=72,0,IF(C7>=71,-4,-8)))))+(MIN(25.5,MAX(0,K7/0.45*25.5))+MIN(17,MAX(0,I7/9.5*17))+MIN(12,MAX(0,N7/6*12))+MIN(11.5,MIN(10,MAX(0,G7/70*10))+MIN(3.75,MAX(0,H7/0.8*3.75)))+MIN(10.25,MAX(0,J7/8*10.25))+MIN(7.5,MAX(0,L7/7*7.5))+MIN(7.5,MAX(0,Q7/90*7.5))+MIN(6.25,MAX(0,P7/78*6.25))-MIN(8,MAX(0,(MAX(0,O7-2)/2)*8))-MIN(8,MAX(0,IF(M7<=1.5,0,IF(M7<=2.5,(M7-1.5)*4,4+(M7-2.5)*8))))-MIN(5,MAX(0,(MAX(0,S7-5)/3)*5))-MIN(3,MAX(0,(MAX(0,R7-2.9)/0.5)*3)))*T7-MAX(0,(W7-22)*3.5))))*0.98)+Z7)) -> 77 | AB7: =IF(AA7=-999,"",IF(AA7>=92,"Franchise QB",IF(AA7>=88,"High-end Starter",IF(AA7>=84,"Developmental Starter",IF(AA7>=71,"Backup / Camp QB",IF(AA7>=58,"Deep Stash","Cut")))))) -> Backup / Camp QB | AC7: CHI | AD7: 1.52
B8: Drew Allar (Penn St.) | C8: 77 | D8: 228 | E8: 4.75 | F8: =ROUND((D8*200)/(E8^4)*(C8/75),2) -> 91.96 | G8: 28.55 | H8: 0.32 | I8: 7.88 | J8: 6.86 | K8: 0.189 | L8: 5.79 | M8: 1.99 | N8: 4.35 | O8: 2.244 | P8: 72.915 | Q8: 75.351 | R8: 2.878 | S8: 4.196 | T8: 1 | U8: =ROUND(MIN(20,MAX(0,K8/0.45*20))+MIN(15,MAX(0,(I8-5)/7*15))+MIN(15,MAX(0,N8/6*15))+MIN(15,MAX(0,G8/80*15))+MIN(15,MAX(0,F8/120*15))+MIN(10,MAX(0,(J8-6)/5*10))+MIN(10,MAX(0,Q8/90*10)),1) -> 52.4 | V8: =ROUND(MIN(25,MAX(0,L8/10*25))+MIN(25,MAX(0,(1-M8/5)*25))+MIN(20,MAX(0,P8/78*20))+MIN(15,MAX(0,(J8-6)/5*15))+MIN(10,MAX(0,(MAX(0,2.5-O8)/2.5)*10))+IF(ISNUMBER(X8),MAX(0,5-((INT(X8)-1)*32+ROUND(MOD(X8,1)*100,0))*0.02),IF(LOWER(X8)="UDFA",0.5,3)),1) -> 55.3 | W8: 23 | X8: 3.12 | Y8: PIT | Z8: =MAX(0,IFERROR(VLOOKUP(Y8,$AC$2:$AD$34,2,FALSE()),0)) -> 1.21 | AA8: =IF(AND(LOWER(X8)="udfa",OR(Y8="N/A",Y8="")),-999,INT(MIN(96.9,(IF((IF(ISNUMBER(X8),12*EXP(-0.0179*((INT(X8)-1)*32+ROUND(MOD(X8,1)*100,0)-1)),IF(LOWER(X8)="UDFA",0.3,0))+IF(C8>=76,8,IF(C8>=74,6,IF(C8>=73,3,IF(C8>=72,0,IF(C8>=71,-4,-8)))))+(MIN(25.5,MAX(0,K8/0.45*25.5))+MIN(17,MAX(0,I8/9.5*17))+MIN(12,MAX(0,N8/6*12))+MIN(11.5,MIN(10,MAX(0,G8/70*10))+MIN(3.75,MAX(0,H8/0.8*3.75)))+MIN(10.25,MAX(0,J8/8*10.25))+MIN(7.5,MAX(0,L8/7*7.5))+MIN(7.5,MAX(0,Q8/90*7.5))+MIN(6.25,MAX(0,P8/78*6.25))-MIN(8,MAX(0,(MAX(0,O8-2)/2)*8))-MIN(8,MAX(0,IF(M8<=1.5,0,IF(M8<=2.5,(M8-1.5)*4,4+(M8-2.5)*8))))-MIN(5,MAX(0,(MAX(0,S8-5)/3)*5))-MIN(3,MAX(0,(MAX(0,R8-2.9)/0.5)*3)))*T8-MAX(0,(W8-22)*3.5))>60,60+SQRT((IF(ISNUMBER(X8),12*EXP(-0.0179*((INT(X8)-1)*32+ROUND(MOD(X8,1)*100,0)-1)),IF(LOWER(X8)="UDFA",0.3,0))+IF(C8>=76,8,IF(C8>=74,6,IF(C8>=73,3,IF(C8>=72,0,IF(C8>=71,-4,-8)))))+(MIN(25.5,MAX(0,K8/0.45*25.5))+MIN(17,MAX(0,I8/9.5*17))+MIN(12,MAX(0,N8/6*12))+MIN(11.5,MIN(10,MAX(0,G8/70*10))+MIN(3.75,MAX(0,H8/0.8*3.75)))+MIN(10.25,MAX(0,J8/8*10.25))+MIN(7.5,MAX(0,L8/7*7.5))+MIN(7.5,MAX(0,Q8/90*7.5))+MIN(6.25,MAX(0,P8/78*6.25))-MIN(8,MAX(0,(MAX(0,O8-2)/2)*8))-MIN(8,MAX(0,IF(M8<=1.5,0,IF(M8<=2.5,(M8-1.5)*4,4+(M8-2.5)*8))))-MIN(5,MAX(0,(MAX(0,S8-5)/3)*5))-MIN(3,MAX(0,(MAX(0,R8-2.9)/0.5)*3)))*T8-MAX(0,(W8-22)*3.5))-60)*5,(IF(ISNUMBER(X8),12*EXP(-0.0179*((INT(X8)-1)*32+ROUND(MOD(X8,1)*100,0)-1)),IF(LOWER(X8)="UDFA",0.3,0))+IF(C8>=76,8,IF(C8>=74,6,IF(C8>=73,3,IF(C8>=72,0,IF(C8>=71,-4,-8)))))+(MIN(25.5,MAX(0,K8/0.45*25.5))+MIN(17,MAX(0,I8/9.5*17))+MIN(12,MAX(0,N8/6*12))+MIN(11.5,MIN(10,MAX(0,G8/70*10))+MIN(3.75,MAX(0,H8/0.8*3.75)))+MIN(10.25,MAX(0,J8/8*10.25))+MIN(7.5,MAX(0,L8/7*7.5))+MIN(7.5,MAX(0,Q8/90*7.5))+MIN(6.25,MAX(0,P8/78*6.25))-MIN(8,MAX(0,(MAX(0,O8-2)/2)*8))-MIN(8,MAX(0,IF(M8<=1.5,0,IF(M8<=2.5,(M8-1.5)*4,4+(M8-2.5)*8))))-MIN(5,MAX(0,(MAX(0,S8-5)/3)*5))-MIN(3,MAX(0,(MAX(0,R8-2.9)/0.5)*3)))*T8-MAX(0,(W8-22)*3.5))))*0.98)+Z8)) -> 76 | AB8: =IF(AA8=-999,"",IF(AA8>=92,"Franchise QB",IF(AA8>=88,"High-end Starter",IF(AA8>=84,"Developmental Starter",IF(AA8>=71,"Backup / Camp QB",IF(AA8>=58,"Deep Stash","Cut")))))) -> Backup / Camp QB | AC8: CIN | AD8: 1.36
B9: Carson Beck (Miami) | C9: 77 | D9: 233 | E9: 4.85 | F9: =ROUND((D9*200)/(E9^4)*(C9/75),2) -> 86.47 | G9: 12.24 | H9: 0.1 | I9: 7.73 | J9: 7.14 | K9: 0.374 | L9: 6.32 | M9: 2.61 | N9: 4.027 | O9: 2.976 | P9: 77.11 | Q9: 77.83 | R9: 2.458 | S9: 3.291 | T9: 1 | U9: =ROUND(MIN(20,MAX(0,K9/0.45*20))+MIN(15,MAX(0,(I9-5)/7*15))+MIN(15,MAX(0,N9/6*15))+MIN(15,MAX(0,G9/80*15))+MIN(15,MAX(0,F9/120*15))+MIN(10,MAX(0,(J9-6)/5*10))+MIN(10,MAX(0,Q9/90*10)),1) -> 56.6 | V9: =ROUND(MIN(25,MAX(0,L9/10*25))+MIN(25,MAX(0,(1-M9/5)*25))+MIN(20,MAX(0,P9/78*20))+MIN(15,MAX(0,(J9-6)/5*15))+MIN(10,MAX(0,(MAX(0,2.5-O9)/2.5)*10))+IF(ISNUMBER(X9),MAX(0,5-((INT(X9)-1)*32+ROUND(MOD(X9,1)*100,0))*0.02),IF(LOWER(X9)="UDFA",0.5,3)),1) -> 54.6 | W9: 24 | X9: 3.01 | Y9: ARI | Z9: =MAX(0,IFERROR(VLOOKUP(Y9,$AC$2:$AD$34,2,FALSE()),0)) -> 1.46 | AA9: =IF(AND(LOWER(X9)="udfa",OR(Y9="N/A",Y9="")),-999,INT(MIN(96.9,(IF((IF(ISNUMBER(X9),12*EXP(-0.0179*((INT(X9)-1)*32+ROUND(MOD(X9,1)*100,0)-1)),IF(LOWER(X9)="UDFA",0.3,0))+IF(C9>=76,8,IF(C9>=74,6,IF(C9>=73,3,IF(C9>=72,0,IF(C9>=71,-4,-8)))))+(MIN(25.5,MAX(0,K9/0.45*25.5))+MIN(17,MAX(0,I9/9.5*17))+MIN(12,MAX(0,N9/6*12))+MIN(11.5,MIN(10,MAX(0,G9/70*10))+MIN(3.75,MAX(0,H9/0.8*3.75)))+MIN(10.25,MAX(0,J9/8*10.25))+MIN(7.5,MAX(0,L9/7*7.5))+MIN(7.5,MAX(0,Q9/90*7.5))+MIN(6.25,MAX(0,P9/78*6.25))-MIN(8,MAX(0,(MAX(0,O9-2)/2)*8))-MIN(8,MAX(0,IF(M9<=1.5,0,IF(M9<=2.5,(M9-1.5)*4,4+(M9-2.5)*8))))-MIN(5,MAX(0,(MAX(0,S9-5)/3)*5))-MIN(3,MAX(0,(MAX(0,R9-2.9)/0.5)*3)))*T9-MAX(0,(W9-22)*3.5))>60,60+SQRT((IF(ISNUMBER(X9),12*EXP(-0.0179*((INT(X9)-1)*32+ROUND(MOD(X9,1)*100,0)-1)),IF(LOWER(X9)="UDFA",0.3,0))+IF(C9>=76,8,IF(C9>=74,6,IF(C9>=73,3,IF(C9>=72,0,IF(C9>=71,-4,-8)))))+(MIN(25.5,MAX(0,K9/0.45*25.5))+MIN(17,MAX(0,I9/9.5*17))+MIN(12,MAX(0,N9/6*12))+MIN(11.5,MIN(10,MAX(0,G9/70*10))+MIN(3.75,MAX(0,H9/0.8*3.75)))+MIN(10.25,MAX(0,J9/8*10.25))+MIN(7.5,MAX(0,L9/7*7.5))+MIN(7.5,MAX(0,Q9/90*7.5))+MIN(6.25,MAX(0,P9/78*6.25))-MIN(8,MAX(0,(MAX(0,O9-2)/2)*8))-MIN(8,MAX(0,IF(M9<=1.5,0,IF(M9<=2.5,(M9-1.5)*4,4+(M9-2.5)*8))))-MIN(5,MAX(0,(MAX(0,S9-5)/3)*5))-MIN(3,MAX(0,(MAX(0,R9-2.9)/0.5)*3)))*T9-MAX(0,(W9-22)*3.5))-60)*5,(IF(ISNUMBER(X9),12*EXP(-0.0179*((INT(X9)-1)*32+ROUND(MOD(X9,1)*100,0)-1)),IF(LOWER(X9)="UDFA",0.3,0))+IF(C9>=76,8,IF(C9>=74,6,IF(C9>=73,3,IF(C9>=72,0,IF(C9>=71,-4,-8)))))+(MIN(25.5,MAX(0,K9/0.45*25.5))+MIN(17,MAX(0,I9/9.5*17))+MIN(12,MAX(0,N9/6*12))+MIN(11.5,MIN(10,MAX(0,G9/70*10))+MIN(3.75,MAX(0,H9/0.8*3.75)))+MIN(10.25,MAX(0,J9/8*10.25))+MIN(7.5,MAX(0,L9/7*7.5))+MIN(7.5,MAX(0,Q9/90*7.5))+MIN(6.25,MAX(0,P9/78*6.25))-MIN(8,MAX(0,(MAX(0,O9-2)/2)*8))-MIN(8,MAX(0,IF(M9<=1.5,0,IF(M9<=2.5,(M9-1.5)*4,4+(M9-2.5)*8))))-MIN(5,MAX(0,(MAX(0,S9-5)/3)*5))-MIN(3,MAX(0,(MAX(0,R9-2.9)/0.5)*3)))*T9-MAX(0,(W9-22)*3.5))))*0.98)+Z9)) -> 75 | AB9: =IF(AA9=-999,"",IF(AA9>=92,"Franchise QB",IF(AA9>=88,"High-end Starter",IF(AA9>=84,"Developmental Starter",IF(AA9>=71,"Backup / Camp QB",IF(AA9>=58,"Deep Stash","Cut")))))) -> Backup / Camp QB | AC9: CLE | AD9: 0.26
B10: Luke Altmyer (Illinois) | C10: 74 | D10: 210 | E10: 4.72 | F10: =ROUND((D10*200)/(E10^4)*(C10/75),2) -> 83.49 | G10: 34.69 | H10: 0.35 | I10: 7.87 | J10: 6.87 | K10: 0.387 | L10: 6.15 | M10: 1.54 | N10: 4.187 | O10: 3.149 | P10: 73.261 | Q10: 74.447 | R10: 2.884 | S10: 7.351 | T10: 1 | U10: =ROUND(MIN(20,MAX(0,K10/0.45*20))+MIN(15,MAX(0,(I10-5)/7*15))+MIN(15,MAX(0,N10/6*15))+MIN(15,MAX(0,G10/80*15))+MIN(15,MAX(0,F10/120*15))+MIN(10,MAX(0,(J10-6)/5*10))+MIN(10,MAX(0,Q10/90*10)),1) -> 60.8 | V10: =ROUND(MIN(25,MAX(0,L10/10*25))+MIN(25,MAX(0,(1-M10/5)*25))+MIN(20,MAX(0,P10/78*20))+MIN(15,MAX(0,(J10-6)/5*15))+MIN(10,MAX(0,(MAX(0,2.5-O10)/2.5)*10))+IF(ISNUMBER(X10),MAX(0,5-((INT(X10)-1)*32+ROUND(MOD(X10,1)*100,0))*0.02),IF(LOWER(X10)="UDFA",0.5,3)),1) -> 54.6 | W10: 24 | X10: UDFA | Y10: DET | Z10: =MAX(0,IFERROR(VLOOKUP(Y10,$AC$2:$AD$34,2,FALSE()),0)) -> 1.59 | AA10: =IF(AND(LOWER(X10)="udfa",OR(Y10="N/A",Y10="")),-999,INT(MIN(96.9,(IF((IF(ISNUMBER(X10),12*EXP(-0.0179*((INT(X10)-1)*32+ROUND(MOD(X10,1)*100,0)-1)),IF(LOWER(X10)="UDFA",0.3,0))+IF(C10>=76,8,IF(C10>=74,6,IF(C10>=73,3,IF(C10>=72,0,IF(C10>=71,-4,-8)))))+(MIN(25.5,MAX(0,K10/0.45*25.5))+MIN(17,MAX(0,I10/9.5*17))+MIN(12,MAX(0,N10/6*12))+MIN(11.5,MIN(10,MAX(0,G10/70*10))+MIN(3.75,MAX(0,H10/0.8*3.75)))+MIN(10.25,MAX(0,J10/8*10.25))+MIN(7.5,MAX(0,L10/7*7.5))+MIN(7.5,MAX(0,Q10/90*7.5))+MIN(6.25,MAX(0,P10/78*6.25))-MIN(8,MAX(0,(MAX(0,O10-2)/2)*8))-MIN(8,MAX(0,IF(M10<=1.5,0,IF(M10<=2.5,(M10-1.5)*4,4+(M10-2.5)*8))))-MIN(5,MAX(0,(MAX(0,S10-5)/3)*5))-MIN(3,MAX(0,(MAX(0,R10-2.9)/0.5)*3)))*T10-MAX(0,(W10-22)*3.5))>60,60+SQRT((IF(ISNUMBER(X10),12*EXP(-0.0179*((INT(X10)-1)*32+ROUND(MOD(X10,1)*100,0)-1)),IF(LOWER(X10)="UDFA",0.3,0))+IF(C10>=76,8,IF(C10>=74,6,IF(C10>=73,3,IF(C10>=72,0,IF(C10>=71,-4,-8)))))+(MIN(25.5,MAX(0,K10/0.45*25.5))+MIN(17,MAX(0,I10/9.5*17))+MIN(12,MAX(0,N10/6*12))+MIN(11.5,MIN(10,MAX(0,G10/70*10))+MIN(3.75,MAX(0,H10/0.8*3.75)))+MIN(10.25,MAX(0,J10/8*10.25))+MIN(7.5,MAX(0,L10/7*7.5))+MIN(7.5,MAX(0,Q10/90*7.5))+MIN(6.25,MAX(0,P10/78*6.25))-MIN(8,MAX(0,(MAX(0,O10-2)/2)*8))-MIN(8,MAX(0,IF(M10<=1.5,0,IF(M10<=2.5,(M10-1.5)*4,4+(M10-2.5)*8))))-MIN(5,MAX(0,(MAX(0,S10-5)/3)*5))-MIN(3,MAX(0,(MAX(0,R10-2.9)/0.5)*3)))*T10-MAX(0,(W10-22)*3.5))-60)*5,(IF(ISNUMBER(X10),12*EXP(-0.0179*((INT(X10)-1)*32+ROUND(MOD(X10,1)*100,0)-1)),IF(LOWER(X10)="UDFA",0.3,0))+IF(C10>=76,8,IF(C10>=74,6,IF(C10>=73,3,IF(C10>=72,0,IF(C10>=71,-4,-8)))))+(MIN(25.5,MAX(0,K10/0.45*25.5))+MIN(17,MAX(0,I10/9.5*17))+MIN(12,MAX(0,N10/6*12))+MIN(11.5,MIN(10,MAX(0,G10/70*10))+MIN(3.75,MAX(0,H10/0.8*3.75)))+MIN(10.25,MAX(0,J10/8*10.25))+MIN(7.5,MAX(0,L10/7*7.5))+MIN(7.5,MAX(0,Q10/90*7.5))+MIN(6.25,MAX(0,P10/78*6.25))-MIN(8,MAX(0,(MAX(0,O10-2)/2)*8))-MIN(8,MAX(0,IF(M10<=1.5,0,IF(M10<=2.5,(M10-1.5)*4,4+(M10-2.5)*8))))-MIN(5,MAX(0,(MAX(0,S10-5)/3)*5))-MIN(3,MAX(0,(MAX(0,R10-2.9)/0.5)*3)))*T10-MAX(0,(W10-22)*3.5))))*0.98)+Z10)) -> 75 | AB10: =IF(AA10=-999,"",IF(AA10>=92,"Franchise QB",IF(AA10>=88,"High-end Starter",IF(AA10>=84,"Developmental Starter",IF(AA10>=71,"Backup / Camp QB",IF(AA10>=58,"Deep Stash","Cut")))))) -> Backup / Camp QB | AC10: DAL | AD10: 2.22
B11: Behren Morton (Texas Tech) | C11: 74 | D11: 221 | E11: 4.88 | F11: =ROUND((D11*200)/(E11^4)*(C11/75),2) -> 76.9 | G11: 9.62 | H11: 0.04 | I11: 7.65 | J11: 6.97 | K11: 0.338 | L11: 6.11 | M11: 1.75 | N11: 5.023 | O11: 3.513 | P11: 74.621 | Q11: 76.124 | R11: 2.665 | S11: 4.887 | T11: 1 | U11: =ROUND(MIN(20,MAX(0,K11/0.45*20))+MIN(15,MAX(0,(I11-5)/7*15))+MIN(15,MAX(0,N11/6*15))+MIN(15,MAX(0,G11/80*15))+MIN(15,MAX(0,F11/120*15))+MIN(10,MAX(0,(J11-6)/5*10))+MIN(10,MAX(0,Q11/90*10)),1) -> 55.1 | V11: =ROUND(MIN(25,MAX(0,L11/10*25))+MIN(25,MAX(0,(1-M11/5)*25))+MIN(20,MAX(0,P11/78*20))+MIN(15,MAX(0,(J11-6)/5*15))+MIN(10,MAX(0,(MAX(0,2.5-O11)/2.5)*10))+IF(ISNUMBER(X11),MAX(0,5-((INT(X11)-1)*32+ROUND(MOD(X11,1)*100,0))*0.02),IF(LOWER(X11)="UDFA",0.5,3)),1) -> 54.1 | W11: 23 | X11: UDFA | Y11: NE | Z11: =MAX(0,IFERROR(VLOOKUP(Y11,$AC$2:$AD$34,2,FALSE()),0)) -> 0.71 | AA11: =IF(AND(LOWER(X11)="udfa",OR(Y11="N/A",Y11="")),-999,INT(MIN(96.9,(IF((IF(ISNUMBER(X11),12*EXP(-0.0179*((INT(X11)-1)*32+ROUND(MOD(X11,1)*100,0)-1)),IF(LOWER(X11)="UDFA",0.3,0))+IF(C11>=76,8,IF(C11>=74,6,IF(C11>=73,3,IF(C11>=72,0,IF(C11>=71,-4,-8)))))+(MIN(25.5,MAX(0,K11/0.45*25.5))+MIN(17,MAX(0,I11/9.5*17))+MIN(12,MAX(0,N11/6*12))+MIN(11.5,MIN(10,MAX(0,G11/70*10))+MIN(3.75,MAX(0,H11/0.8*3.75)))+MIN(10.25,MAX(0,J11/8*10.25))+MIN(7.5,MAX(0,L11/7*7.5))+MIN(7.5,MAX(0,Q11/90*7.5))+MIN(6.25,MAX(0,P11/78*6.25))-MIN(8,MAX(0,(MAX(0,O11-2)/2)*8))-MIN(8,MAX(0,IF(M11<=1.5,0,IF(M11<=2.5,(M11-1.5)*4,4+(M11-2.5)*8))))-MIN(5,MAX(0,(MAX(0,S11-5)/3)*5))-MIN(3,MAX(0,(MAX(0,R11-2.9)/0.5)*3)))*T11-MAX(0,(W11-22)*3.5))>60,60+SQRT((IF(ISNUMBER(X11),12*EXP(-0.0179*((INT(X11)-1)*32+ROUND(MOD(X11,1)*100,0)-1)),IF(LOWER(X11)="UDFA",0.3,0))+IF(C11>=76,8,IF(C11>=74,6,IF(C11>=73,3,IF(C11>=72,0,IF(C11>=71,-4,-8)))))+(MIN(25.5,MAX(0,K11/0.45*25.5))+MIN(17,MAX(0,I11/9.5*17))+MIN(12,MAX(0,N11/6*12))+MIN(11.5,MIN(10,MAX(0,G11/70*10))+MIN(3.75,MAX(0,H11/0.8*3.75)))+MIN(10.25,MAX(0,J11/8*10.25))+MIN(7.5,MAX(0,L11/7*7.5))+MIN(7.5,MAX(0,Q11/90*7.5))+MIN(6.25,MAX(0,P11/78*6.25))-MIN(8,MAX(0,(MAX(0,O11-2)/2)*8))-MIN(8,MAX(0,IF(M11<=1.5,0,IF(M11<=2.5,(M11-1.5)*4,4+(M11-2.5)*8))))-MIN(5,MAX(0,(MAX(0,S11-5)/3)*5))-MIN(3,MAX(0,(MAX(0,R11-2.9)/0.5)*3)))*T11-MAX(0,(W11-22)*3.5))-60)*5,(IF(ISNUMBER(X11),12*EXP(-0.0179*((INT(X11)-1)*32+ROUND(MOD(X11,1)*100,0)-1)),IF(LOWER(X11)="UDFA",0.3,0))+IF(C11>=76,8,IF(C11>=74,6,IF(C11>=73,3,IF(C11>=72,0,IF(C11>=71,-4,-8)))))+(MIN(25.5,MAX(0,K11/0.45*25.5))+MIN(17,MAX(0,I11/9.5*17))+MIN(12,MAX(0,N11/6*12))+MIN(11.5,MIN(10,MAX(0,G11/70*10))+MIN(3.75,MAX(0,H11/0.8*3.75)))+MIN(10.25,MAX(0,J11/8*10.25))+MIN(7.5,MAX(0,L11/7*7.5))+MIN(7.5,MAX(0,Q11/90*7.5))+MIN(6.25,MAX(0,P11/78*6.25))-MIN(8,MAX(0,(MAX(0,O11-2)/2)*8))-MIN(8,MAX(0,IF(M11<=1.5,0,IF(M11<=2.5,(M11-1.5)*4,4+(M11-2.5)*8))))-MIN(5,MAX(0,(MAX(0,S11-5)/3)*5))-MIN(3,MAX(0,(MAX(0,R11-2.9)/0.5)*3)))*T11-MAX(0,(W11-22)*3.5))))*0.98)+Z11)) -> 73 | AB11: =IF(AA11=-999,"",IF(AA11>=92,"Franchise QB",IF(AA11>=88,"High-end Starter",IF(AA11>=84,"Developmental Starter",IF(AA11>=71,"Backup / Camp QB",IF(AA11>=58,"Deep Stash","Cut")))))) -> Backup / Camp QB | AC11: DEN | AD11: 2.39
B12: Joe Fagnano (Connecticut); Sleeper*** | C12: 75 | D12: 226 | E12: 4.83 | F12: =ROUND((D12*200)/(E12^4)*(C12/75),2) -> 83.05 | G12: 14 | H12: 0.18 | I12: 9.06 | J12: 7.54 | K12: 0.464 | L12: 7.73 | M12: 0.81 | N12: 3.2 | O12: 1.7 | P12: 75.89 | Q12: 77.624 | R12: 2.5 | S12: 3.237 | T12: 0.85 | U12: =ROUND(MIN(20,MAX(0,K12/0.45*20))+MIN(15,MAX(0,(I12-5)/7*15))+MIN(15,MAX(0,N12/6*15))+MIN(15,MAX(0,G12/80*15))+MIN(15,MAX(0,F12/120*15))+MIN(10,MAX(0,(J12-6)/5*10))+MIN(10,MAX(0,Q12/90*10)),1) -> 61.4 | V12: =ROUND(MIN(25,MAX(0,L12/10*25))+MIN(25,MAX(0,(1-M12/5)*25))+MIN(20,MAX(0,P12/78*20))+MIN(15,MAX(0,(J12-6)/5*15))+MIN(10,MAX(0,(MAX(0,2.5-O12)/2.5)*10))+IF(ISNUMBER(X12),MAX(0,5-((INT(X12)-1)*32+ROUND(MOD(X12,1)*100,0))*0.02),IF(LOWER(X12)="UDFA",0.5,3)),1) -> 68.1 | W12: 25 | X12: UDFA | Y12: BAL | Z12: =MAX(0,IFERROR(VLOOKUP(Y12,$AC$2:$AD$34,2,FALSE()),0)) -> 0.97 | AA12: =IF(AND(LOWER(X12)="udfa",OR(Y12="N/A",Y12="")),-999,INT(MIN(96.9,(IF((IF(ISNUMBER(X12),12*EXP(-0.0179*((INT(X12)-1)*32+ROUND(MOD(X12,1)*100,0)-1)),IF(LOWER(X12)="UDFA",0.3,0))+IF(C12>=76,8,IF(C12>=74,6,IF(C12>=73,3,IF(C12>=72,0,IF(C12>=71,-4,-8)))))+(MIN(25.5,MAX(0,K12/0.45*25.5))+MIN(17,MAX(0,I12/9.5*17))+MIN(12,MAX(0,N12/6*12))+MIN(11.5,MIN(10,MAX(0,G12/70*10))+MIN(3.75,MAX(0,H12/0.8*3.75)))+MIN(10.25,MAX(0,J12/8*10.25))+MIN(7.5,MAX(0,L12/7*7.5))+MIN(7.5,MAX(0,Q12/90*7.5))+MIN(6.25,MAX(0,P12/78*6.25))-MIN(8,MAX(0,(MAX(0,O12-2)/2)*8))-MIN(8,MAX(0,IF(M12<=1.5,0,IF(M12<=2.5,(M12-1.5)*4,4+(M12-2.5)*8))))-MIN(5,MAX(0,(MAX(0,S12-5)/3)*5))-MIN(3,MAX(0,(MAX(0,R12-2.9)/0.5)*3)))*T12-MAX(0,(W12-22)*3.5))>60,60+SQRT((IF(ISNUMBER(X12),12*EXP(-0.0179*((INT(X12)-1)*32+ROUND(MOD(X12,1)*100,0)-1)),IF(LOWER(X12)="UDFA",0.3,0))+IF(C12>=76,8,IF(C12>=74,6,IF(C12>=73,3,IF(C12>=72,0,IF(C12>=71,-4,-8)))))+(MIN(25.5,MAX(0,K12/0.45*25.5))+MIN(17,MAX(0,I12/9.5*17))+MIN(12,MAX(0,N12/6*12))+MIN(11.5,MIN(10,MAX(0,G12/70*10))+MIN(3.75,MAX(0,H12/0.8*3.75)))+MIN(10.25,MAX(0,J12/8*10.25))+MIN(7.5,MAX(0,L12/7*7.5))+MIN(7.5,MAX(0,Q12/90*7.5))+MIN(6.25,MAX(0,P12/78*6.25))-MIN(8,MAX(0,(MAX(0,O12-2)/2)*8))-MIN(8,MAX(0,IF(M12<=1.5,0,IF(M12<=2.5,(M12-1.5)*4,4+(M12-2.5)*8))))-MIN(5,MAX(0,(MAX(0,S12-5)/3)*5))-MIN(3,MAX(0,(MAX(0,R12-2.9)/0.5)*3)))*T12-MAX(0,(W12-22)*3.5))-60)*5,(IF(ISNUMBER(X12),12*EXP(-0.0179*((INT(X12)-1)*32+ROUND(MOD(X12,1)*100,0)-1)),IF(LOWER(X12)="UDFA",0.3,0))+IF(C12>=76,8,IF(C12>=74,6,IF(C12>=73,3,IF(C12>=72,0,IF(C12>=71,-4,-8)))))+(MIN(25.5,MAX(0,K12/0.45*25.5))+MIN(17,MAX(0,I12/9.5*17))+MIN(12,MAX(0,N12/6*12))+MIN(11.5,MIN(10,MAX(0,G12/70*10))+MIN(3.75,MAX(0,H12/0.8*3.75)))+MIN(10.25,MAX(0,J12/8*10.25))+MIN(7.5,MAX(0,L12/7*7.5))+MIN(7.5,MAX(0,Q12/90*7.5))+MIN(6.25,MAX(0,P12/78*6.25))-MIN(8,MAX(0,(MAX(0,O12-2)/2)*8))-MIN(8,MAX(0,IF(M12<=1.5,0,IF(M12<=2.5,(M12-1.5)*4,4+(M12-2.5)*8))))-MIN(5,MAX(0,(MAX(0,S12-5)/3)*5))-MIN(3,MAX(0,(MAX(0,R12-2.9)/0.5)*3)))*T12-MAX(0,(W12-22)*3.5))))*0.98)+Z12)) -> 70 | AB12: =IF(AA12=-999,"",IF(AA12>=92,"Franchise QB",IF(AA12>=88,"High-end Starter",IF(AA12>=84,"Developmental Starter",IF(AA12>=71,"Backup / Camp QB",IF(AA12>=58,"Deep Stash","Cut")))))) -> Deep Stash | AC12: DET | AD12: 1.59
B13: Taylen Green (Arkansas) | C13: 77.875 | D13: 227 | E13: 4.36 | F13: =ROUND((D13*200)/(E13^4)*(C13/75),2) -> 130.45 | G13: 72.68 | H13: 0.64 | I13: 7.29 | J13: 6.88 | K13: 0.332 | L13: 4.76 | M13: 2.8 | N13: 4.438 | O13: 4.385 | P13: 70.649 | Q13: 72.919 | R13: 3.195 | S13: 6.954 | T13: 1 | U13: =ROUND(MIN(20,MAX(0,K13/0.45*20))+MIN(15,MAX(0,(I13-5)/7*15))+MIN(15,MAX(0,N13/6*15))+MIN(15,MAX(0,G13/80*15))+MIN(15,MAX(0,F13/120*15))+MIN(10,MAX(0,(J13-6)/5*10))+MIN(10,MAX(0,Q13/90*10)),1) -> 69.2 | V13: =ROUND(MIN(25,MAX(0,L13/10*25))+MIN(25,MAX(0,(1-M13/5)*25))+MIN(20,MAX(0,P13/78*20))+MIN(15,MAX(0,(J13-6)/5*15))+MIN(10,MAX(0,(MAX(0,2.5-O13)/2.5)*10))+IF(ISNUMBER(X13),MAX(0,5-((INT(X13)-1)*32+ROUND(MOD(X13,1)*100,0))*0.02),IF(LOWER(X13)="UDFA",0.5,3)),1) -> 45 | W13: 23 | X13: 6.22 | Y13: CLE | Z13: =MAX(0,IFERROR(VLOOKUP(Y13,$AC$2:$AD$34,2,FALSE()),0)) -> 0.26 | AA13: =IF(AND(LOWER(X13)="udfa",OR(Y13="N/A",Y13="")),-999,INT(MIN(96.9,(IF((IF(ISNUMBER(X13),12*EXP(-0.0179*((INT(X13)-1)*32+ROUND(MOD(X13,1)*100,0)-1)),IF(LOWER(X13)="UDFA",0.3,0))+IF(C13>=76,8,IF(C13>=74,6,IF(C13>=73,3,IF(C13>=72,0,IF(C13>=71,-4,-8)))))+(MIN(25.5,MAX(0,K13/0.45*25.5))+MIN(17,MAX(0,I13/9.5*17))+MIN(12,MAX(0,N13/6*12))+MIN(11.5,MIN(10,MAX(0,G13/70*10))+MIN(3.75,MAX(0,H13/0.8*3.75)))+MIN(10.25,MAX(0,J13/8*10.25))+MIN(7.5,MAX(0,L13/7*7.5))+MIN(7.5,MAX(0,Q13/90*7.5))+MIN(6.25,MAX(0,P13/78*6.25))-MIN(8,MAX(0,(MAX(0,O13-2)/2)*8))-MIN(8,MAX(0,IF(M13<=1.5,0,IF(M13<=2.5,(M13-1.5)*4,4+(M13-2.5)*8))))-MIN(5,MAX(0,(MAX(0,S13-5)/3)*5))-MIN(3,MAX(0,(MAX(0,R13-2.9)/0.5)*3)))*T13-MAX(0,(W13-22)*3.5))>60,60+SQRT((IF(ISNUMBER(X13),12*EXP(-0.0179*((INT(X13)-1)*32+ROUND(MOD(X13,1)*100,0)-1)),IF(LOWER(X13)="UDFA",0.3,0))+IF(C13>=76,8,IF(C13>=74,6,IF(C13>=73,3,IF(C13>=72,0,IF(C13>=71,-4,-8)))))+(MIN(25.5,MAX(0,K13/0.45*25.5))+MIN(17,MAX(0,I13/9.5*17))+MIN(12,MAX(0,N13/6*12))+MIN(11.5,MIN(10,MAX(0,G13/70*10))+MIN(3.75,MAX(0,H13/0.8*3.75)))+MIN(10.25,MAX(0,J13/8*10.25))+MIN(7.5,MAX(0,L13/7*7.5))+MIN(7.5,MAX(0,Q13/90*7.5))+MIN(6.25,MAX(0,P13/78*6.25))-MIN(8,MAX(0,(MAX(0,O13-2)/2)*8))-MIN(8,MAX(0,IF(M13<=1.5,0,IF(M13<=2.5,(M13-1.5)*4,4+(M13-2.5)*8))))-MIN(5,MAX(0,(MAX(0,S13-5)/3)*5))-MIN(3,MAX(0,(MAX(0,R13-2.9)/0.5)*3)))*T13-MAX(0,(W13-22)*3.5))-60)*5,(IF(ISNUMBER(X13),12*EXP(-0.0179*((INT(X13)-1)*32+ROUND(MOD(X13,1)*100,0)-1)),IF(LOWER(X13)="UDFA",0.3,0))+IF(C13>=76,8,IF(C13>=74,6,IF(C13>=73,3,IF(C13>=72,0,IF(C13>=71,-4,-8)))))+(MIN(25.5,MAX(0,K13/0.45*25.5))+MIN(17,MAX(0,I13/9.5*17))+MIN(12,MAX(0,N13/6*12))+MIN(11.5,MIN(10,MAX(0,G13/70*10))+MIN(3.75,MAX(0,H13/0.8*3.75)))+MIN(10.25,MAX(0,J13/8*10.25))+MIN(7.5,MAX(0,L13/7*7.5))+MIN(7.5,MAX(0,Q13/90*7.5))+MIN(6.25,MAX(0,P13/78*6.25))-MIN(8,MAX(0,(MAX(0,O13-2)/2)*8))-MIN(8,MAX(0,IF(M13<=1.5,0,IF(M13<=2.5,(M13-1.5)*4,4+(M13-2.5)*8))))-MIN(5,MAX(0,(MAX(0,S13-5)/3)*5))-MIN(3,MAX(0,(MAX(0,R13-2.9)/0.5)*3)))*T13-MAX(0,(W13-22)*3.5))))*0.98)+Z13)) -> 68 | AB13: =IF(AA13=-999,"",IF(AA13>=92,"Franchise QB",IF(AA13>=88,"High-end Starter",IF(AA13>=84,"Developmental Starter",IF(AA13>=71,"Backup / Camp QB",IF(AA13>=58,"Deep Stash","Cut")))))) -> Deep Stash | AC13: GB | AD13: 1.16
B14: Cole Payton (NDSU) | C14: 75 | D14: 232 | E14: 4.56 | F14: =ROUND((D14*200)/(E14^4)*(C14/75),2) -> 107.31 | G14: 59.8 | H14: 1 | I14: 11.39 | J14: 10.83 | K14: 0.569 | L14: 6.93 | M14: 1.73 | N14: 11.3 | O14: 1.5 | P14: 72 | Q14: 94.6 | R14: 3.33 | S14: 7.97 | T14: 0.7 | U14: =ROUND(MIN(20,MAX(0,K14/0.45*20))+MIN(15,MAX(0,(I14-5)/7*15))+MIN(15,MAX(0,N14/6*15))+MIN(15,MAX(0,G14/80*15))+MIN(15,MAX(0,F14/120*15))+MIN(10,MAX(0,(J14-6)/5*10))+MIN(10,MAX(0,Q14/90*10)),1) -> 93 | V14: =ROUND(MIN(25,MAX(0,L14/10*25))+MIN(25,MAX(0,(1-M14/5)*25))+MIN(20,MAX(0,P14/78*20))+MIN(15,MAX(0,(J14-6)/5*15))+MIN(10,MAX(0,(MAX(0,2.5-O14)/2.5)*10))+IF(ISNUMBER(X14),MAX(0,5-((INT(X14)-1)*32+ROUND(MOD(X14,1)*100,0))*0.02),IF(LOWER(X14)="UDFA",0.5,3)),1) -> 72.1 | W14: 24 | X14: 6.18 | Y14: PHI | Z14: =MAX(0,IFERROR(VLOOKUP(Y14,$AC$2:$AD$34,2,FALSE()),0)) -> 1.64 | AA14: =IF(AND(LOWER(X14)="udfa",OR(Y14="N/A",Y14="")),-999,INT(MIN(96.9,(IF((IF(ISNUMBER(X14),12*EXP(-0.0179*((INT(X14)-1)*32+ROUND(MOD(X14,1)*100,0)-1)),IF(LOWER(X14)="UDFA",0.3,0))+IF(C14>=76,8,IF(C14>=74,6,IF(C14>=73,3,IF(C14>=72,0,IF(C14>=71,-4,-8)))))+(MIN(25.5,MAX(0,K14/0.45*25.5))+MIN(17,MAX(0,I14/9.5*17))+MIN(12,MAX(0,N14/6*12))+MIN(11.5,MIN(10,MAX(0,G14/70*10))+MIN(3.75,MAX(0,H14/0.8*3.75)))+MIN(10.25,MAX(0,J14/8*10.25))+MIN(7.5,MAX(0,L14/7*7.5))+MIN(7.5,MAX(0,Q14/90*7.5))+MIN(6.25,MAX(0,P14/78*6.25))-MIN(8,MAX(0,(MAX(0,O14-2)/2)*8))-MIN(8,MAX(0,IF(M14<=1.5,0,IF(M14<=2.5,(M14-1.5)*4,4+(M14-2.5)*8))))-MIN(5,MAX(0,(MAX(0,S14-5)/3)*5))-MIN(3,MAX(0,(MAX(0,R14-2.9)/0.5)*3)))*T14-MAX(0,(W14-22)*3.5))>60,60+SQRT((IF(ISNUMBER(X14),12*EXP(-0.0179*((INT(X14)-1)*32+ROUND(MOD(X14,1)*100,0)-1)),IF(LOWER(X14)="UDFA",0.3,0))+IF(C14>=76,8,IF(C14>=74,6,IF(C14>=73,3,IF(C14>=72,0,IF(C14>=71,-4,-8)))))+(MIN(25.5,MAX(0,K14/0.45*25.5))+MIN(17,MAX(0,I14/9.5*17))+MIN(12,MAX(0,N14/6*12))+MIN(11.5,MIN(10,MAX(0,G14/70*10))+MIN(3.75,MAX(0,H14/0.8*3.75)))+MIN(10.25,MAX(0,J14/8*10.25))+MIN(7.5,MAX(0,L14/7*7.5))+MIN(7.5,MAX(0,Q14/90*7.5))+MIN(6.25,MAX(0,P14/78*6.25))-MIN(8,MAX(0,(MAX(0,O14-2)/2)*8))-MIN(8,MAX(0,IF(M14<=1.5,0,IF(M14<=2.5,(M14-1.5)*4,4+(M14-2.5)*8))))-MIN(5,MAX(0,(MAX(0,S14-5)/3)*5))-MIN(3,MAX(0,(MAX(0,R14-2.9)/0.5)*3)))*T14-MAX(0,(W14-22)*3.5))-60)*5,(IF(ISNUMBER(X14),12*EXP(-0.0179*((INT(X14)-1)*32+ROUND(MOD(X14,1)*100,0)-1)),IF(LOWER(X14)="UDFA",0.3,0))+IF(C14>=76,8,IF(C14>=74,6,IF(C14>=73,3,IF(C14>=72,0,IF(C14>=71,-4,-8)))))+(MIN(25.5,MAX(0,K14/0.45*25.5))+MIN(17,MAX(0,I14/9.5*17))+MIN(12,MAX(0,N14/6*12))+MIN(11.5,MIN(10,MAX(0,G14/70*10))+MIN(3.75,MAX(0,H14/0.8*3.75)))+MIN(10.25,MAX(0,J14/8*10.25))+MIN(7.5,MAX(0,L14/7*7.5))+MIN(7.5,MAX(0,Q14/90*7.5))+MIN(6.25,MAX(0,P14/78*6.25))-MIN(8,MAX(0,(MAX(0,O14-2)/2)*8))-MIN(8,MAX(0,IF(M14<=1.5,0,IF(M14<=2.5,(M14-1.5)*4,4+(M14-2.5)*8))))-MIN(5,MAX(0,(MAX(0,S14-5)/3)*5))-MIN(3,MAX(0,(MAX(0,R14-2.9)/0.5)*3)))*T14-MAX(0,(W14-22)*3.5))))*0.98)+Z14)) -> 66 | AB14: =IF(AA14=-999,"",IF(AA14>=92,"Franchise QB",IF(AA14>=88,"High-end Starter",IF(AA14>=84,"Developmental Starter",IF(AA14>=71,"Backup / Camp QB",IF(AA14>=58,"Deep Stash","Cut")))))) -> Deep Stash | AC14: HOU | AD14: 0.02
B15: Garrett Nussmeier (LSU) | C15: 74 | D15: 203 | E15: 4.82 | F15: =ROUND((D15*200)/(E15^4)*(C15/75),2) -> 74.22 | G15: 7.14 | H15: 0.18 | I15: 7.14 | J15: 6.91 | K15: 0.2 | L15: 5.04 | M15: 2.09 | N15: 4.628 | O15: 3.064 | P15: 73.516 | Q15: 79.54 | R15: 2.602 | S15: 3.454 | T15: 1 | U15: =ROUND(MIN(20,MAX(0,K15/0.45*20))+MIN(15,MAX(0,(I15-5)/7*15))+MIN(15,MAX(0,N15/6*15))+MIN(15,MAX(0,G15/80*15))+MIN(15,MAX(0,F15/120*15))+MIN(10,MAX(0,(J15-6)/5*10))+MIN(10,MAX(0,Q15/90*10)),1) -> 46.3 | V15: =ROUND(MIN(25,MAX(0,L15/10*25))+MIN(25,MAX(0,(1-M15/5)*25))+MIN(20,MAX(0,P15/78*20))+MIN(15,MAX(0,(J15-6)/5*15))+MIN(10,MAX(0,(MAX(0,2.5-O15)/2.5)*10))+IF(ISNUMBER(X15),MAX(0,5-((INT(X15)-1)*32+ROUND(MOD(X15,1)*100,0))*0.02),IF(LOWER(X15)="UDFA",0.5,3)),1) -> 48.8 | W15: 22 | X15: 7.57 | Y15: KC | Z15: =MAX(0,IFERROR(VLOOKUP(Y15,$AC$2:$AD$34,2,FALSE()),0)) -> 1.21 | AA15: =IF(AND(LOWER(X15)="udfa",OR(Y15="N/A",Y15="")),-999,INT(MIN(96.9,(IF((IF(ISNUMBER(X15),12*EXP(-0.0179*((INT(X15)-1)*32+ROUND(MOD(X15,1)*100,0)-1)),IF(LOWER(X15)="UDFA",0.3,0))+IF(C15>=76,8,IF(C15>=74,6,IF(C15>=73,3,IF(C15>=72,0,IF(C15>=71,-4,-8)))))+(MIN(25.5,MAX(0,K15/0.45*25.5))+MIN(17,MAX(0,I15/9.5*17))+MIN(12,MAX(0,N15/6*12))+MIN(11.5,MIN(10,MAX(0,G15/70*10))+MIN(3.75,MAX(0,H15/0.8*3.75)))+MIN(10.25,MAX(0,J15/8*10.25))+MIN(7.5,MAX(0,L15/7*7.5))+MIN(7.5,MAX(0,Q15/90*7.5))+MIN(6.25,MAX(0,P15/78*6.25))-MIN(8,MAX(0,(MAX(0,O15-2)/2)*8))-MIN(8,MAX(0,IF(M15<=1.5,0,IF(M15<=2.5,(M15-1.5)*4,4+(M15-2.5)*8))))-MIN(5,MAX(0,(MAX(0,S15-5)/3)*5))-MIN(3,MAX(0,(MAX(0,R15-2.9)/0.5)*3)))*T15-MAX(0,(W15-22)*3.5))>60,60+SQRT((IF(ISNUMBER(X15),12*EXP(-0.0179*((INT(X15)-1)*32+ROUND(MOD(X15,1)*100,0)-1)),IF(LOWER(X15)="UDFA",0.3,0))+IF(C15>=76,8,IF(C15>=74,6,IF(C15>=73,3,IF(C15>=72,0,IF(C15>=71,-4,-8)))))+(MIN(25.5,MAX(0,K15/0.45*25.5))+MIN(17,MAX(0,I15/9.5*17))+MIN(12,MAX(0,N15/6*12))+MIN(11.5,MIN(10,MAX(0,G15/70*10))+MIN(3.75,MAX(0,H15/0.8*3.75)))+MIN(10.25,MAX(0,J15/8*10.25))+MIN(7.5,MAX(0,L15/7*7.5))+MIN(7.5,MAX(0,Q15/90*7.5))+MIN(6.25,MAX(0,P15/78*6.25))-MIN(8,MAX(0,(MAX(0,O15-2)/2)*8))-MIN(8,MAX(0,IF(M15<=1.5,0,IF(M15<=2.5,(M15-1.5)*4,4+(M15-2.5)*8))))-MIN(5,MAX(0,(MAX(0,S15-5)/3)*5))-MIN(3,MAX(0,(MAX(0,R15-2.9)/0.5)*3)))*T15-MAX(0,(W15-22)*3.5))-60)*5,(IF(ISNUMBER(X15),12*EXP(-0.0179*((INT(X15)-1)*32+ROUND(MOD(X15,1)*100,0)-1)),IF(LOWER(X15)="UDFA",0.3,0))+IF(C15>=76,8,IF(C15>=74,6,IF(C15>=73,3,IF(C15>=72,0,IF(C15>=71,-4,-8)))))+(MIN(25.5,MAX(0,K15/0.45*25.5))+MIN(17,MAX(0,I15/9.5*17))+MIN(12,MAX(0,N15/6*12))+MIN(11.5,MIN(10,MAX(0,G15/70*10))+MIN(3.75,MAX(0,H15/0.8*3.75)))+MIN(10.25,MAX(0,J15/8*10.25))+MIN(7.5,MAX(0,L15/7*7.5))+MIN(7.5,MAX(0,Q15/90*7.5))+MIN(6.25,MAX(0,P15/78*6.25))-MIN(8,MAX(0,(MAX(0,O15-2)/2)*8))-MIN(8,MAX(0,IF(M15<=1.5,0,IF(M15<=2.5,(M15-1.5)*4,4+(M15-2.5)*8))))-MIN(5,MAX(0,(MAX(0,S15-5)/3)*5))-MIN(3,MAX(0,(MAX(0,R15-2.9)/0.5)*3)))*T15-MAX(0,(W15-22)*3.5))))*0.98)+Z15)) -> 66 | AB15: =IF(AA15=-999,"",IF(AA15>=92,"Franchise QB",IF(AA15>=88,"High-end Starter",IF(AA15>=84,"Developmental Starter",IF(AA15>=71,"Backup / Camp QB",IF(AA15>=58,"Deep Stash","Cut")))))) -> Deep Stash | AC15: IND | AD15: 1.5
B16: Jalon Daniels (Kansas) | C16: 73 | D16: 219 | E16: 4.65 | F16: =ROUND((D16*200)/(E16^4)*(C16/75),2) -> 91.19 | G16: 43.33 | H16: 0.42 | I16: 7.46 | J16: 7.08 | K16: 0.376 | L16: 5.79 | M16: 3.05 | N16: 6.207 | O16: 4.09 | P16: 69.232 | Q16: 72.285 | R16: 2.975 | S16: 3.961 | T16: 1 | U16: =ROUND(MIN(20,MAX(0,K16/0.45*20))+MIN(15,MAX(0,(I16-5)/7*15))+MIN(15,MAX(0,N16/6*15))+MIN(15,MAX(0,G16/80*15))+MIN(15,MAX(0,F16/120*15))+MIN(10,MAX(0,(J16-6)/5*10))+MIN(10,MAX(0,Q16/90*10)),1) -> 66.7 | V16: =ROUND(MIN(25,MAX(0,L16/10*25))+MIN(25,MAX(0,(1-M16/5)*25))+MIN(20,MAX(0,P16/78*20))+MIN(15,MAX(0,(J16-6)/5*15))+MIN(10,MAX(0,(MAX(0,2.5-O16)/2.5)*10))+IF(ISNUMBER(X16),MAX(0,5-((INT(X16)-1)*32+ROUND(MOD(X16,1)*100,0))*0.02),IF(LOWER(X16)="UDFA",0.5,3)),1) -> 45.7 | W16: 24 | X16: UDFA | Y16: TB | Z16: =MAX(0,IFERROR(VLOOKUP(Y16,$AC$2:$AD$34,2,FALSE()),0)) -> 1.45 | AA16: =IF(AND(LOWER(X16)="udfa",OR(Y16="N/A",Y16="")),-999,INT(MIN(96.9,(IF((IF(ISNUMBER(X16),12*EXP(-0.0179*((INT(X16)-1)*32+ROUND(MOD(X16,1)*100,0)-1)),IF(LOWER(X16)="UDFA",0.3,0))+IF(C16>=76,8,IF(C16>=74,6,IF(C16>=73,3,IF(C16>=72,0,IF(C16>=71,-4,-8)))))+(MIN(25.5,MAX(0,K16/0.45*25.5))+MIN(17,MAX(0,I16/9.5*17))+MIN(12,MAX(0,N16/6*12))+MIN(11.5,MIN(10,MAX(0,G16/70*10))+MIN(3.75,MAX(0,H16/0.8*3.75)))+MIN(10.25,MAX(0,J16/8*10.25))+MIN(7.5,MAX(0,L16/7*7.5))+MIN(7.5,MAX(0,Q16/90*7.5))+MIN(6.25,MAX(0,P16/78*6.25))-MIN(8,MAX(0,(MAX(0,O16-2)/2)*8))-MIN(8,MAX(0,IF(M16<=1.5,0,IF(M16<=2.5,(M16-1.5)*4,4+(M16-2.5)*8))))-MIN(5,MAX(0,(MAX(0,S16-5)/3)*5))-MIN(3,MAX(0,(MAX(0,R16-2.9)/0.5)*3)))*T16-MAX(0,(W16-22)*3.5))>60,60+SQRT((IF(ISNUMBER(X16),12*EXP(-0.0179*((INT(X16)-1)*32+ROUND(MOD(X16,1)*100,0)-1)),IF(LOWER(X16)="UDFA",0.3,0))+IF(C16>=76,8,IF(C16>=74,6,IF(C16>=73,3,IF(C16>=72,0,IF(C16>=71,-4,-8)))))+(MIN(25.5,MAX(0,K16/0.45*25.5))+MIN(17,MAX(0,I16/9.5*17))+MIN(12,MAX(0,N16/6*12))+MIN(11.5,MIN(10,MAX(0,G16/70*10))+MIN(3.75,MAX(0,H16/0.8*3.75)))+MIN(10.25,MAX(0,J16/8*10.25))+MIN(7.5,MAX(0,L16/7*7.5))+MIN(7.5,MAX(0,Q16/90*7.5))+MIN(6.25,MAX(0,P16/78*6.25))-MIN(8,MAX(0,(MAX(0,O16-2)/2)*8))-MIN(8,MAX(0,IF(M16<=1.5,0,IF(M16<=2.5,(M16-1.5)*4,4+(M16-2.5)*8))))-MIN(5,MAX(0,(MAX(0,S16-5)/3)*5))-MIN(3,MAX(0,(MAX(0,R16-2.9)/0.5)*3)))*T16-MAX(0,(W16-22)*3.5))-60)*5,(IF(ISNUMBER(X16),12*EXP(-0.0179*((INT(X16)-1)*32+ROUND(MOD(X16,1)*100,0)-1)),IF(LOWER(X16)="UDFA",0.3,0))+IF(C16>=76,8,IF(C16>=74,6,IF(C16>=73,3,IF(C16>=72,0,IF(C16>=71,-4,-8)))))+(MIN(25.5,MAX(0,K16/0.45*25.5))+MIN(17,MAX(0,I16/9.5*17))+MIN(12,MAX(0,N16/6*12))+MIN(11.5,MIN(10,MAX(0,G16/70*10))+MIN(3.75,MAX(0,H16/0.8*3.75)))+MIN(10.25,MAX(0,J16/8*10.25))+MIN(7.5,MAX(0,L16/7*7.5))+MIN(7.5,MAX(0,Q16/90*7.5))+MIN(6.25,MAX(0,P16/78*6.25))-MIN(8,MAX(0,(MAX(0,O16-2)/2)*8))-MIN(8,MAX(0,IF(M16<=1.5,0,IF(M16<=2.5,(M16-1.5)*4,4+(M16-2.5)*8))))-MIN(5,MAX(0,(MAX(0,S16-5)/3)*5))-MIN(3,MAX(0,(MAX(0,R16-2.9)/0.5)*3)))*T16-MAX(0,(W16-22)*3.5))))*0.98)+Z16)) -> 66 | AB16: =IF(AA16=-999,"",IF(AA16>=92,"Franchise QB",IF(AA16>=88,"High-end Starter",IF(AA16>=84,"Developmental Starter",IF(AA16>=71,"Backup / Camp QB",IF(AA16>=58,"Deep Stash","Cut")))))) -> Deep Stash | AC16: JAC | AD16: 0.43
B17: Sawyer Robertson (Baylor) | C17: 76 | D17: 216 | E17: 4.64 | F17: =ROUND((D17*200)/(E17^4)*(C17/75),2) -> 94.44 | G17: 20.46 | H17: 0.29 | I17: 7.73 | J17: 7.07 | K17: 0.252 | L17: 6.77 | M17: 2.3 | N17: 4.257 | O17: 3.6 | P17: 67.873 | Q17: 70.462 | R17: 2.547 | S17: 3.9 | T17: 1 | U17: =ROUND(MIN(20,MAX(0,K17/0.45*20))+MIN(15,MAX(0,(I17-5)/7*15))+MIN(15,MAX(0,N17/6*15))+MIN(15,MAX(0,G17/80*15))+MIN(15,MAX(0,F17/120*15))+MIN(10,MAX(0,(J17-6)/5*10))+MIN(10,MAX(0,Q17/90*10)),1) -> 53.3 | V17: =ROUND(MIN(25,MAX(0,L17/10*25))+MIN(25,MAX(0,(1-M17/5)*25))+MIN(20,MAX(0,P17/78*20))+MIN(15,MAX(0,(J17-6)/5*15))+MIN(10,MAX(0,(MAX(0,2.5-O17)/2.5)*10))+IF(ISNUMBER(X17),MAX(0,5-((INT(X17)-1)*32+ROUND(MOD(X17,1)*100,0))*0.02),IF(LOWER(X17)="UDFA",0.5,3)),1) -> 51.5 | W17: 25 | X17: UDFA | Y17: LV | Z17: =MAX(0,IFERROR(VLOOKUP(Y17,$AC$2:$AD$34,2,FALSE()),0)) -> 0.5 | AA17: =IF(AND(LOWER(X17)="udfa",OR(Y17="N/A",Y17="")),-999,INT(MIN(96.9,(IF((IF(ISNUMBER(X17),12*EXP(-0.0179*((INT(X17)-1)*32+ROUND(MOD(X17,1)*100,0)-1)),IF(LOWER(X17)="UDFA",0.3,0))+IF(C17>=76,8,IF(C17>=74,6,IF(C17>=73,3,IF(C17>=72,0,IF(C17>=71,-4,-8)))))+(MIN(25.5,MAX(0,K17/0.45*25.5))+MIN(17,MAX(0,I17/9.5*17))+MIN(12,MAX(0,N17/6*12))+MIN(11.5,MIN(10,MAX(0,G17/70*10))+MIN(3.75,MAX(0,H17/0.8*3.75)))+MIN(10.25,MAX(0,J17/8*10.25))+MIN(7.5,MAX(0,L17/7*7.5))+MIN(7.5,MAX(0,Q17/90*7.5))+MIN(6.25,MAX(0,P17/78*6.25))-MIN(8,MAX(0,(MAX(0,O17-2)/2)*8))-MIN(8,MAX(0,IF(M17<=1.5,0,IF(M17<=2.5,(M17-1.5)*4,4+(M17-2.5)*8))))-MIN(5,MAX(0,(MAX(0,S17-5)/3)*5))-MIN(3,MAX(0,(MAX(0,R17-2.9)/0.5)*3)))*T17-MAX(0,(W17-22)*3.5))>60,60+SQRT((IF(ISNUMBER(X17),12*EXP(-0.0179*((INT(X17)-1)*32+ROUND(MOD(X17,1)*100,0)-1)),IF(LOWER(X17)="UDFA",0.3,0))+IF(C17>=76,8,IF(C17>=74,6,IF(C17>=73,3,IF(C17>=72,0,IF(C17>=71,-4,-8)))))+(MIN(25.5,MAX(0,K17/0.45*25.5))+MIN(17,MAX(0,I17/9.5*17))+MIN(12,MAX(0,N17/6*12))+MIN(11.5,MIN(10,MAX(0,G17/70*10))+MIN(3.75,MAX(0,H17/0.8*3.75)))+MIN(10.25,MAX(0,J17/8*10.25))+MIN(7.5,MAX(0,L17/7*7.5))+MIN(7.5,MAX(0,Q17/90*7.5))+MIN(6.25,MAX(0,P17/78*6.25))-MIN(8,MAX(0,(MAX(0,O17-2)/2)*8))-MIN(8,MAX(0,IF(M17<=1.5,0,IF(M17<=2.5,(M17-1.5)*4,4+(M17-2.5)*8))))-MIN(5,MAX(0,(MAX(0,S17-5)/3)*5))-MIN(3,MAX(0,(MAX(0,R17-2.9)/0.5)*3)))*T17-MAX(0,(W17-22)*3.5))-60)*5,(IF(ISNUMBER(X17),12*EXP(-0.0179*((INT(X17)-1)*32+ROUND(MOD(X17,1)*100,0)-1)),IF(LOWER(X17)="UDFA",0.3,0))+IF(C17>=76,8,IF(C17>=74,6,IF(C17>=73,3,IF(C17>=72,0,IF(C17>=71,-4,-8)))))+(MIN(25.5,MAX(0,K17/0.45*25.5))+MIN(17,MAX(0,I17/9.5*17))+MIN(12,MAX(0,N17/6*12))+MIN(11.5,MIN(10,MAX(0,G17/70*10))+MIN(3.75,MAX(0,H17/0.8*3.75)))+MIN(10.25,MAX(0,J17/8*10.25))+MIN(7.5,MAX(0,L17/7*7.5))+MIN(7.5,MAX(0,Q17/90*7.5))+MIN(6.25,MAX(0,P17/78*6.25))-MIN(8,MAX(0,(MAX(0,O17-2)/2)*8))-MIN(8,MAX(0,IF(M17<=1.5,0,IF(M17<=2.5,(M17-1.5)*4,4+(M17-2.5)*8))))-MIN(5,MAX(0,(MAX(0,S17-5)/3)*5))-MIN(3,MAX(0,(MAX(0,R17-2.9)/0.5)*3)))*T17-MAX(0,(W17-22)*3.5))))*0.98)+Z17)) -> 56 | AB17: =IF(AA17=-999,"",IF(AA17>=92,"Franchise QB",IF(AA17>=88,"High-end Starter",IF(AA17>=84,"Developmental Starter",IF(AA17>=71,"Backup / Camp QB",IF(AA17>=58,"Deep Stash","Cut")))))) -> Cut | AC17: JAX | AD17: 0.43
B18: Miller Moss (Louisville) | C18: 74 | D18: 210 | E18: 4.9 | F18: =ROUND((D18*200)/(E18^4)*(C18/75),2) -> 71.88 | G18: 6.05 | H18: 0.52 | I18: 6.67 | J18: 6.61 | K18: 0.126 | L18: 4.55 | M18: 2.14 | N18: 3.558 | O18: 3.733 | P18: 72.293 | Q18: 69.058 | R18: 2.606 | S18: 3.929 | T18: 1 | U18: =ROUND(MIN(20,MAX(0,K18/0.45*20))+MIN(15,MAX(0,(I18-5)/7*15))+MIN(15,MAX(0,N18/6*15))+MIN(15,MAX(0,G18/80*15))+MIN(15,MAX(0,F18/120*15))+MIN(10,MAX(0,(J18-6)/5*10))+MIN(10,MAX(0,Q18/90*10)),1) -> 37.1 | V18: =ROUND(MIN(25,MAX(0,L18/10*25))+MIN(25,MAX(0,(1-M18/5)*25))+MIN(20,MAX(0,P18/78*20))+MIN(15,MAX(0,(J18-6)/5*15))+MIN(10,MAX(0,(MAX(0,2.5-O18)/2.5)*10))+IF(ISNUMBER(X18),MAX(0,5-((INT(X18)-1)*32+ROUND(MOD(X18,1)*100,0))*0.02),IF(LOWER(X18)="UDFA",0.5,3)),1) -> 46.5 | W18: 24 | X18: UDFA | Y18: CHI | Z18: =MAX(0,IFERROR(VLOOKUP(Y18,$AC$2:$AD$34,2,FALSE()),0)) -> 1.52 | AA18: =IF(AND(LOWER(X18)="udfa",OR(Y18="N/A",Y18="")),-999,INT(MIN(96.9,(IF((IF(ISNUMBER(X18),12*EXP(-0.0179*((INT(X18)-1)*32+ROUND(MOD(X18,1)*100,0)-1)),IF(LOWER(X18)="UDFA",0.3,0))+IF(C18>=76,8,IF(C18>=74,6,IF(C18>=73,3,IF(C18>=72,0,IF(C18>=71,-4,-8)))))+(MIN(25.5,MAX(0,K18/0.45*25.5))+MIN(17,MAX(0,I18/9.5*17))+MIN(12,MAX(0,N18/6*12))+MIN(11.5,MIN(10,MAX(0,G18/70*10))+MIN(3.75,MAX(0,H18/0.8*3.75)))+MIN(10.25,MAX(0,J18/8*10.25))+MIN(7.5,MAX(0,L18/7*7.5))+MIN(7.5,MAX(0,Q18/90*7.5))+MIN(6.25,MAX(0,P18/78*6.25))-MIN(8,MAX(0,(MAX(0,O18-2)/2)*8))-MIN(8,MAX(0,IF(M18<=1.5,0,IF(M18<=2.5,(M18-1.5)*4,4+(M18-2.5)*8))))-MIN(5,MAX(0,(MAX(0,S18-5)/3)*5))-MIN(3,MAX(0,(MAX(0,R18-2.9)/0.5)*3)))*T18-MAX(0,(W18-22)*3.5))>60,60+SQRT((IF(ISNUMBER(X18),12*EXP(-0.0179*((INT(X18)-1)*32+ROUND(MOD(X18,1)*100,0)-1)),IF(LOWER(X18)="UDFA",0.3,0))+IF(C18>=76,8,IF(C18>=74,6,IF(C18>=73,3,IF(C18>=72,0,IF(C18>=71,-4,-8)))))+(MIN(25.5,MAX(0,K18/0.45*25.5))+MIN(17,MAX(0,I18/9.5*17))+MIN(12,MAX(0,N18/6*12))+MIN(11.5,MIN(10,MAX(0,G18/70*10))+MIN(3.75,MAX(0,H18/0.8*3.75)))+MIN(10.25,MAX(0,J18/8*10.25))+MIN(7.5,MAX(0,L18/7*7.5))+MIN(7.5,MAX(0,Q18/90*7.5))+MIN(6.25,MAX(0,P18/78*6.25))-MIN(8,MAX(0,(MAX(0,O18-2)/2)*8))-MIN(8,MAX(0,IF(M18<=1.5,0,IF(M18<=2.5,(M18-1.5)*4,4+(M18-2.5)*8))))-MIN(5,MAX(0,(MAX(0,S18-5)/3)*5))-MIN(3,MAX(0,(MAX(0,R18-2.9)/0.5)*3)))*T18-MAX(0,(W18-22)*3.5))-60)*5,(IF(ISNUMBER(X18),12*EXP(-0.0179*((INT(X18)-1)*32+ROUND(MOD(X18,1)*100,0)-1)),IF(LOWER(X18)="UDFA",0.3,0))+IF(C18>=76,8,IF(C18>=74,6,IF(C18>=73,3,IF(C18>=72,0,IF(C18>=71,-4,-8)))))+(MIN(25.5,MAX(0,K18/0.45*25.5))+MIN(17,MAX(0,I18/9.5*17))+MIN(12,MAX(0,N18/6*12))+MIN(11.5,MIN(10,MAX(0,G18/70*10))+MIN(3.75,MAX(0,H18/0.8*3.75)))+MIN(10.25,MAX(0,J18/8*10.25))+MIN(7.5,MAX(0,L18/7*7.5))+MIN(7.5,MAX(0,Q18/90*7.5))+MIN(6.25,MAX(0,P18/78*6.25))-MIN(8,MAX(0,(MAX(0,O18-2)/2)*8))-MIN(8,MAX(0,IF(M18<=1.5,0,IF(M18<=2.5,(M18-1.5)*4,4+(M18-2.5)*8))))-MIN(5,MAX(0,(MAX(0,S18-5)/3)*5))-MIN(3,MAX(0,(MAX(0,R18-2.9)/0.5)*3)))*T18-MAX(0,(W18-22)*3.5))))*0.98)+Z18)) -> 44 | AB18: =IF(AA18=-999,"",IF(AA18>=92,"Franchise QB",IF(AA18>=88,"High-end Starter",IF(AA18>=84,"Developmental Starter",IF(AA18>=71,"Backup / Camp QB",IF(AA18>=58,"Deep Stash","Cut")))))) -> Cut | AC18: KC | AD18: 1.21
B19: Kyron Drones (Virginia Tech) | C19: 73 | D19: 233 | E19: 4.65 | F19: =ROUND((D19*200)/(E19^4)*(C19/75),2) -> 97.01 | G19: 58.81 | H19: 0.71 | I19: 5.8 | J19: 5.44 | K19: 0.131 | L19: 4.98 | M19: 2.77 | N19: 4.221 | O19: 4.182 | P19: 69.591 | Q19: 65.978 | R19: 3.082 | S19: 5.943 | T19: 1 | U19: =ROUND(MIN(20,MAX(0,K19/0.45*20))+MIN(15,MAX(0,(I19-5)/7*15))+MIN(15,MAX(0,N19/6*15))+MIN(15,MAX(0,G19/80*15))+MIN(15,MAX(0,F19/120*15))+MIN(10,MAX(0,(J19-6)/5*10))+MIN(10,MAX(0,Q19/90*10)),1) -> 48.6 | V19: =ROUND(MIN(25,MAX(0,L19/10*25))+MIN(25,MAX(0,(1-M19/5)*25))+MIN(20,MAX(0,P19/78*20))+MIN(15,MAX(0,(J19-6)/5*15))+MIN(10,MAX(0,(MAX(0,2.5-O19)/2.5)*10))+IF(ISNUMBER(X19),MAX(0,5-((INT(X19)-1)*32+ROUND(MOD(X19,1)*100,0))*0.02),IF(LOWER(X19)="UDFA",0.5,3)),1) -> 41.9 | W19: 24 | X19: UDFA | Y19: GB | Z19: =MAX(0,IFERROR(VLOOKUP(Y19,$AC$2:$AD$34,2,FALSE()),0)) -> 1.16 | AA19: =IF(AND(LOWER(X19)="udfa",OR(Y19="N/A",Y19="")),-999,INT(MIN(96.9,(IF((IF(ISNUMBER(X19),12*EXP(-0.0179*((INT(X19)-1)*32+ROUND(MOD(X19,1)*100,0)-1)),IF(LOWER(X19)="UDFA",0.3,0))+IF(C19>=76,8,IF(C19>=74,6,IF(C19>=73,3,IF(C19>=72,0,IF(C19>=71,-4,-8)))))+(MIN(25.5,MAX(0,K19/0.45*25.5))+MIN(17,MAX(0,I19/9.5*17))+MIN(12,MAX(0,N19/6*12))+MIN(11.5,MIN(10,MAX(0,G19/70*10))+MIN(3.75,MAX(0,H19/0.8*3.75)))+MIN(10.25,MAX(0,J19/8*10.25))+MIN(7.5,MAX(0,L19/7*7.5))+MIN(7.5,MAX(0,Q19/90*7.5))+MIN(6.25,MAX(0,P19/78*6.25))-MIN(8,MAX(0,(MAX(0,O19-2)/2)*8))-MIN(8,MAX(0,IF(M19<=1.5,0,IF(M19<=2.5,(M19-1.5)*4,4+(M19-2.5)*8))))-MIN(5,MAX(0,(MAX(0,S19-5)/3)*5))-MIN(3,MAX(0,(MAX(0,R19-2.9)/0.5)*3)))*T19-MAX(0,(W19-22)*3.5))>60,60+SQRT((IF(ISNUMBER(X19),12*EXP(-0.0179*((INT(X19)-1)*32+ROUND(MOD(X19,1)*100,0)-1)),IF(LOWER(X19)="UDFA",0.3,0))+IF(C19>=76,8,IF(C19>=74,6,IF(C19>=73,3,IF(C19>=72,0,IF(C19>=71,-4,-8)))))+(MIN(25.5,MAX(0,K19/0.45*25.5))+MIN(17,MAX(0,I19/9.5*17))+MIN(12,MAX(0,N19/6*12))+MIN(11.5,MIN(10,MAX(0,G19/70*10))+MIN(3.75,MAX(0,H19/0.8*3.75)))+MIN(10.25,MAX(0,J19/8*10.25))+MIN(7.5,MAX(0,L19/7*7.5))+MIN(7.5,MAX(0,Q19/90*7.5))+MIN(6.25,MAX(0,P19/78*6.25))-MIN(8,MAX(0,(MAX(0,O19-2)/2)*8))-MIN(8,MAX(0,IF(M19<=1.5,0,IF(M19<=2.5,(M19-1.5)*4,4+(M19-2.5)*8))))-MIN(5,MAX(0,(MAX(0,S19-5)/3)*5))-MIN(3,MAX(0,(MAX(0,R19-2.9)/0.5)*3)))*T19-MAX(0,(W19-22)*3.5))-60)*5,(IF(ISNUMBER(X19),12*EXP(-0.0179*((INT(X19)-1)*32+ROUND(MOD(X19,1)*100,0)-1)),IF(LOWER(X19)="UDFA",0.3,0))+IF(C19>=76,8,IF(C19>=74,6,IF(C19>=73,3,IF(C19>=72,0,IF(C19>=71,-4,-8)))))+(MIN(25.5,MAX(0,K19/0.45*25.5))+MIN(17,MAX(0,I19/9.5*17))+MIN(12,MAX(0,N19/6*12))+MIN(11.5,MIN(10,MAX(0,G19/70*10))+MIN(3.75,MAX(0,H19/0.8*3.75)))+MIN(10.25,MAX(0,J19/8*10.25))+MIN(7.5,MAX(0,L19/7*7.5))+MIN(7.5,MAX(0,Q19/90*7.5))+MIN(6.25,MAX(0,P19/78*6.25))-MIN(8,MAX(0,(MAX(0,O19-2)/2)*8))-MIN(8,MAX(0,IF(M19<=1.5,0,IF(M19<=2.5,(M19-1.5)*4,4+(M19-2.5)*8))))-MIN(5,MAX(0,(MAX(0,S19-5)/3)*5))-MIN(3,MAX(0,(MAX(0,R19-2.9)/0.5)*3)))*T19-MAX(0,(W19-22)*3.5))))*0.98)+Z19)) -> 40 | AB19: =IF(AA19=-999,"",IF(AA19>=92,"Franchise QB",IF(AA19>=88,"High-end Starter",IF(AA19>=84,"Developmental Starter",IF(AA19>=71,"Backup / Camp QB",IF(AA19>=58,"Deep Stash","Cut")))))) -> Cut | AC19: LAC | AD19: 1.34
